Workbook

Sheet (총괄)신청내역표
A2: 2026년 디지털새싹 프로그램 운영 사업비 신청내역표
A5: 연번 | B5: 과정 구분 | C5: 학교급 | D5: 교육소양 | E5: 교육 프로그램명 | F5: 단가 기준 신청(제출) 금액(공급대가(부가세 포함) 기준 작성) | M5: 세부 내역 기준 신청(제출) 금액(공급대가(부가세 포함) 기준 작성)
M6: 회 | T6: ※ 사업관리비 및 간접비는 총액 기준 작성 | W6: 합계
F7: 1인 교육단가 (A) | G7: 수업인원(B) * 1개 클래스 기준 예상 평균 | H7: 운영 횟수 (C) | I7: 목표인원 (D=BxC) | J7: 프로그램 운영비 합계 (부가세 포함) (E=AxD) | K7: 수업차시 | L7: 시간당 단가 | M7: 직접비 | V7: 간접비
M8: 사업운영비 | R8: 사업관리비
M9: 시설·장비 임차비 | N9: 재료구입비 | O9: 인쇄·복사·인화· 슬라이드 제작비 (교재) | P9: 외부 전문가 기술 활용비 | Q9: 그 외 운영비 | R9: 인건비 | S9: 사업수당 | T9: 인쇄·복사·인화· 슬라이드 제작비(홍보) | U9: 그 외 관리비
A10: 1 | B10: 기본 | C10: 초저(1~4학년) | D10: 디지털 리터러시 | E10: AI 인터렉티브아트 창작자 | F10: =A프로그램!N27/'(총괄)신청내역표'!I10 -> 136985.7 | G10: 20 | H10: 36 | I10: 660 | J10: =F10*I10 -> 90410560 | K10: 8 | L10: =J10/I10/K10 -> 17123.212 | M10: =A프로그램!N5+A프로그램!N6 -> 3390000 | N10: =A프로그램!N8+A프로그램!N9 -> 13450560 | O10: 0 | P10: =SUM(A프로그램!N12:N16) -> 52360000 | Q10: =SUM(A프로그램!N17:N23) -> 21210000 | R10: =SUM('총 사업비 산출'!N34:N39) -> 104800000 | S10: ='총 사업비 산출'!N40+'총 사업비 산출'!N41 -> 7200000 | T10: ='총 사업비 산출'!N44 -> 3000000 | U10: =SUM('총 사업비 산출'!N42:N43)+'총 사업비 산출'!N45+'총 사업비 산출'!N46 -> 27800000 | V10: 47600000 | W10: =SUM(M10:Q16)+SUM(R10:V10) -> 992320000
A11: 2 | B11: 기본 | C11: 초고(5~6학년) | D11: 인공지능소양 | E11: AI배달 로봇 엔지니어 | F11: =B프로그램!N26/'(총괄)신청내역표'!I11 -> 183178.56 | G11: 20 | H11: 36 | I11: 720 | J11: =F11*I11 -> 131888560 | K11: 8 | L11: =J11/I11/K11 -> 22897.319 | M11: =B프로그램!N5 -> 2880000 | N11: =B프로그램!N8+B프로그램!N9 -> 63118560 | O11: 0 | P11: =SUM(B프로그램!N12:N16) -> 44680000 | Q11: =SUM(B프로그램!N17:N23) -> 21210000
A12: 3 | B12: 기본 | C12: 다문화 | D12: 인공지능소양 | E12: 다문화 AI 큐레이터 | F12: =C프로그램!N26/'(총괄)신청내역표'!I12 -> 155839.27 | G12: 20 | H12: 36 | I12: 600 | J12: =F12*I12 -> 93503560 | K12: 8 | L12: =J12/I12/K12 -> 19479.908 | M12: =C프로그램!N5 -> 2880000 | N12: =C프로그램!N8+C프로그램!N9 -> 16233560 | O12: 0 | P12: =SUM(C프로그램!N12:N16) -> 52360000 | Q12: =SUM(C프로그램!N17:N23) -> 22030000
A13: 4 | B13: 기본 | C13: 중등 | D13: 인공지능소양 | E13: 재난안전 AI로봇 운용관 | F13: =D프로그램!N26/'(총괄)신청내역표'!I13 -> 181818.2 | G13: 20 | H13: 36 | I13: 800 | J13: =F13*I13 -> 145454560 | K13: 8 | L13: =J13/I13/K13 -> 22727.275 | M13: =D프로그램!N5 -> 2880000 | N13: =D프로그램!N8+D프로그램!N9 -> 68184560 | O13: 0 | P13: =SUM(D프로그램!N12:N16) -> 52360000 | Q13: =SUM(D프로그램!N17:N23) -> 22030000
A14: 5 | B14: 기본 | C14: 중등 | D14: 데이터소양 | E14: AI데이터 분석관 | F14: =E프로그램!N26/'(총괄)신청내역표'!I14 -> 147180.56 | G14: 20 | H14: 36 | I14: 640 | J14: =F14*I14 -> 94195560 | K14: 8 | L14: =J14/I14/K14 -> 18397.57 | M14: =E프로그램!N5+E프로그램!N6 -> 3110000 | N14: =E프로그램!N8+E프로그램!N9 -> 16695560 | O14: 0 | P14: =SUM(E프로그램!N12:N16) -> 52360000 | Q14: =SUM(E프로그램!N17:N23) -> 22030000
A15: 6 | B15: 특화(AI 특화) | C15: 고등 | D15: 인공지능소양 | E15: 강화학습 자율주행AI 개발자(Sim2Real) | F15: =F프로그램!N26/'(총괄)신청내역표'!I15 -> 303815.71 | G15: 15 | H15: 37 | I15: 420 | J15: =F15*I15 -> 1.276026e+08 | K15: 12 | L15: =J15/I15/K15 -> 25317.976 | M15: =F프로그램!N5+F프로그램!N6+F프로그램!N7 -> 5610000 | N15: =F프로그램!N8+F프로그램!N9 -> 43382600 | O15: 0 | P15: =SUM(F프로그램!N12:N16) -> 55160000 | Q15: =SUM(F프로그램!N17:N23) -> 23450000
A16: 7 | B16: 특화(AI 특화) | C16: 고등 | D16: 인공지능소양 | E16: 피지컬AI 어플리케이션 개발자 | F16: =G프로그램!N27/'(총괄)신청내역표'!I16 -> 330179.44 | G16: 15 | H16: 36 | I16: 360 | J16: =F16*I16 -> 118864600 | K16: 12 | L16: =J16/I16/K16 -> 27514.954 | M16: =G프로그램!N5+G프로그램!N6+G프로그램!N7+G프로그램!N8 -> 5800000 | N16: =G프로그램!N9+G프로그램!N10 -> 35634600 | O16: 0 | P16: =SUM(G프로그램!N13:N17) -> 53980000 | Q16: =SUM(G프로그램!N18:N24) -> 23450000
A17: 합계 및 평균 | F17: =AVERAGE(F10:F16) -> 205571.06 | G17: =SUM(G10:G16) -> 130 | H17: =SUM(H10:H16) -> 253 | I17: =SUM(I10:I16) -> 4200 | J17: =SUM(J10:J16) -> 801920000 | K17: =SUM(K10:K16) -> 64 | L17: =AVERAGE(L10:L16) -> 21922.602 | M17: =SUM(M10:M16) -> 26550000 | N17: =SUM(N10:N16) -> 256700000 | O17: =SUM(O10:O16) -> 0 | P17: =SUM(P10:P16) -> 363260000 | Q17: =SUM(Q10:Q16) -> 155410000 | R17: =R10 -> 104800000 | S17: =S10 -> 7200000 | T17: =T10 -> 3000000 | U17: =U10 -> 27800000 | V17: =V10 -> 47600000 | W17: =SUM(W10:W16) -> 992320000

Sheet (공통)_강사료 지급 기준 및 명단
B1: 강사료 지급 기준 및 참여 명단
B3: 1. 지급 기준
B4: 구분 | C4: 주강사 | F4: 보조강사 | I4: 단기인력(안전관리 포함) | L4: 외부 전문가
B5: 등급 | C5: 적용대상 | D5: 시간당 금액 | E5: 수업 1회 최대 지급액 | F5: 적용대상 | G5: 시간당 금액 | H5: 수업 1회 최대 지급액 | I5: 적용대상 | J5: 시간당 금액 | K5: 수업 1회 최대 지급액 | L5: 적용대상 | M5: 시간당 금액 | N5: 수업 1회 최대 지급액
B6: 가 | C6: - 교사, 방과후전문강사, 교수, 기업소속 전문가 - 위 모두 기존 디지털새싹 또는 유사 강의 2 클래스 이상 주강사로 참여했거나, AI융합대학원 졸업 또는 재학중인 자 | D6: 100000 | E6: 300000 | F6: - 교사, 방과후전문강사, 교수, 기업소속 전문가 - 위 모두 기존 디지털새싹 또는 유사 강의 2 클래스 이상 보조강사로 참여했거나, AI융합대학원 졸업 또는 재학중인 자 | G6: 60000 | H6: 180000 | I6: 교사, 방과후 전문강사 | J6: 20000 | K6: 60000 | L6: 컴퓨터 관련 전공 박사이상, 정보관련 교사 경력 20년 이상 또는 부장, 대학 전임교원 이상, 기업체소속 전문가(책임연구원 이상) | M6: 회 | N6: 1000000
B7: 나 | C7: - 교사, 방과후전문강사, 교수, 기업소속 전문가 - 단, 위 모두 인하대 디지털새싹에서 진행하는 강사교육 4시간이상 수료자로 소정의 대면 평가를 통과한 자 | D7: 75000 | E7: 300000 | F7: - 교사, 방과후전문강사, 기업소속 전문가 - 단, 위 모두 인하대 디지털새싹에서 진행하는 강사교육 4시간이상 수료자 | G7: 45000 | H7: 180000 | I7: 일반인, 대학원생, 대학생 | J7: 15000 | K7: 60000 | L7: 컴퓨터 관련 전공 석사이상, 정보관련 교사, 연구원(책임급 미만) | M7: 400000 | N7: 800000
B8: 다 | C8: - 대학생, 대학원생(석박사과정 포함) - 단, 위 모두 강사교육 4시간 이상 수료자로 보조강사로 2클래스 이상 참여한 자 | D8: 50000 | E8: 300000 | F8: - 대학생, 대학원생(석박사과정 포함) - 단, 위 모두 강사교육 8시간 이상 수료자 | G8: 30000 | H8: 180000
B10: 2. 강사진 및 전문가 구성 명단
B11: ※ 칸이 부족할 경우 아래로 추가하여 작성
B12: 연번 | C12: 참여 구분 | D12: 참여 프로그램 | E12: 등급 | F12: 강사명 (가나다순) | G12: 생년월일 | H12: 소속 | J12: 최종학력(졸업기준) | M12: 관련 자격증 (취득일자) | N12: 해당분야 경력(년) | O12: 활동 가능 권역 | P12: 관련 주요 경력 | Q12: 총 투입시간 | R12: 확정여부
H13: 기관명 | I13: 직위 | J13: 학교명 | K13: 구분 | L13: 전공
B14: 1 | C14: 주강사 | D14: 페트병의 모래를 흔들어라 - 에너지 ON | E14: 가 | F14: 김세호 | G14: 19730325 | H14: 광성중학교 | I14: 교사 | J14: 인하대학교 교육대학원 | K14: 석사 | L14: AI융합교육 | M14: 정교사 1정 자격증 | N14: 26 | O14: 서울 인천지역 | P14: 인하대 잡스의 차고캠프 강사(23~현재), 인하대학교 교육학과 겸임교수(22~현재) | Q14: 8 | R14: 확정
B15: 2 | C15: 주강사 | D15: 페트병의 모래를 흔들어라 - 에너지 ON | E15: 나 | F15: 임채용 | G15: 19750722 | H15: 명신여자고등학교 | I15: 교사 | J15: 성균관대학교 물리학과 | K15: 학사 | L15: 물리학 (인공지능융합 대학원 이수중) | M15: - | N15: 6 | O15: 서울 인천지역 | P15: 인공지능 융합 선도학교/중심학교 담당 부장 | Q15: 8 | R15: 확정
B16: 3 | C16: 주강사 | D16: 페트병의 모래를 흔들어라 - 에너지 ON | E16: 가 | F16: 박종화 | G16: 19750105 | H16: 옥련중학교 | I16: 교사 | J16: 금오공과대학교 | K16: 학사 | L16: 산업공학과 | M16: - | N16: 24 | O16: 서울 인천지역 | P16: 인하대 잡스의 차고캠프 강사(23~현재), 인하대학원 AI융합대학원 재중 | Q16: 8 | R16: 확정
B17: 4 | C17: 보조강사 | D17: 페트병의 모래를 흔들어라 - 에너지 ON | E17: 가 | F17: 오상희 | G17: 19670217 | H17: 서울대학교사범대학부설중학교 | I17: 교사 | J17: 성균관대학교 | K17: 석사 | L17: 인공지능융합교육, 컴퓨터교육 | M17: 정보컴퓨터(1998.2.23.) | N17: 31 | O17: 서울 인천지역 | P17: 서울대학교사범대학부설중학교('23~현재) 서울대학교사범대학부설고등학교('15~'23) 숨문고등학교('99~'15) | Q17: 8 | R17: 확정
B18: 5 | C18: 주강사 | D18: 페트병의 모래를 흔들어라 - 에너지 ON | E18: 나 | F18: 이선주 | G18: 19831207 | H18: 언남중학교 | I18: 교사 | J18: 경기대 교육대학원 | K18: 석사 | L18: 기술교육 | M18: 중등1급정교사 2019년 9월15일 | N18: 10 | O18: 서울 인천지역 | P18: 인하대 잡스의 차고캠프 강사(23~현재) | Q18: 8 | R18: 확정
B19: 6 | C19: 주강사 | D19: 페트병의 모래를 흔들어라 - 에너지 ON | E19: 가 | F19: 유경윤 | G19: 19840423 | H19: 인천부내초등학교 | I19: 교사 | J19: 인하대학교 교육대학원 | K19: 석사 | L19: AI융합교육 | M19: - | N19: 16 | O19: 서울 인천지역 | P19: 인하대 잡스의 차고캠프 강사(23~현재) 20-21년 초등 블랜디드수업 지원단 20~23년 정보교육지원단 디지털 선도학교 터치교사단 대표교원 2023 AIEDAP 마스터교원 | Q19: 8 | R19: 확정
B20: 7 | C20: 주강사 | D20: 페트병의 모래를 흔들어라 - 에너지 ON | E20: 가 | F20: 이정한 | G20: 19890527 | H20: 인천이음초등학교 | I20: 교사 | J20: 인하대학교 교육대학원 | K20: 석사 | L20: AI융합교육 | M20: AI융합대학원 석사 | N20: 6 | O20: 서울 인천지역 | P20: 인하대 잡스의 차고캠프 강사(23~현재) | Q20: 8 | R20: 확정
B21: 8 | C21: 보조강사 | D21: 페트병의 모래를 흔들어라 - 에너지 ON | E21: 가 | F21: 김병욱 | G21: 19770622 | H21: 인천금융고등학교 | I21: 교사 | J21: 건국대학교 교육대학원 | K21: 석사 | L21: 미술교육 | M21: 중등학교정교사(1급) 미술(20190411) | N21: 21 | O21: 서울 인천지역 | P21: (주)교학사 편집3부('08~'11년) 중등예술영재교육원 예술영재학급 미술강사('18~22년) 경희대학교 교육대학원 겸임교수('22년) 안산본오중, 인하사대부중, 정석항공과학고, 인천금융고('11~현재) 인하대 잡스의 차고캠프 강사(23~현재) | Q21: 8 | R21: 확정
B22: 9 | C22: 보조강사 | D22: 페트병의 모래를 흔들어라 - 에너지 ON | E22: 가 | F22: 남혜진 | G22: 19770428 | H22: 부흥중학교 | I22: 교사 | J22: 인하대학교 교육대학원 | K22: 석사 | L22: AISTEAM교육 | M22: 중등정교사 1금 | N22: 11 | O22: 서울 인천지역 | P22: 인하대 잡스의 차고캠프 강사(23~현재) | Q22: 8 | R22: 확정
B23: 10 | C23: 보조강사 | D23: 페트병의 모래를 흔들어라 - 에너지 ON | E23: 가 | F23: 우민경 | G23: 19900905 | H23: 서울가락초 | I23: 교사 | J23: 서울교육대학교 교육대학원 | K23: 석사 | L23: 국제사회문화교육 | M23: 교원자격증 2013년 2월 | N23: 11 | O23: 서울 인천지역 | P23: 인하대 잡스의 차고캠프 강사 22~현재 | Q23: 8 | R23: 확정
B24: 11 | C24: 주강사 | D24: 인터랙티브 모션아트 : AI응용 체험교실 | E24: 가 | F24: 장희욱 | G24: 19901123 | H24: 인천초은중학교 | I24: 교사 | J24: 인하대학교 교육대학원 | K24: 석사 | L24: AI융합교육 | M24: - | N24: 7 | O24: 서울 인천지역 | P24: 인하대 잡스의 차고캠프 강사(23~현재) | Q24: 8 | R24: 확정
B25: 12 | C25: 주강사 | D25: 인터랙티브 모션아트 : AI응용 체험교실 | E25: 가 | F25: 이우진 | G25: 19760526 | H25: 프리랜서 강사 | I25: 전문강사 | J25: 건국대학교 | K25: 학사 | L25: 전자공학과 | M25: 정보처리기사(2003.6.9) | N25: 30 | O25: 서울 인천지역 | P25: 프로그래밍 동아리 부트 회장 및 강사 역임('96년) 씨컴인터내셔널 개발팀장('00년) 정부프로젝트 DSP를 이용한 MPEG4 코덱개발('01~'02년) 이지엠텍 SW팀('03~'09년) 유니모 SW팀장('09~'13년) 엠이티글로벌 SW팀장('13~'21년) 프리랜서 프로그래밍 강의 및 개발('21~현재) | Q25: 8 | R25: 확정
... B54: 41 | C54: 보조강사 | D54: 광량과 입사각에 따른 태양광 발전효율 선형회귀분석 | E54: 나 | F54: 공예린 | G54: 19980731 | H54: 인천영종초등학교 | I54: 교사 | J54: 경인교육대학교 | K54: 학사 | L54: 초등교육 | M54: AI-900(23.11.11) | N54: 4 | O54: 서울 인천지역 | P54: 인하대 잡스의 차고캠프 강사(23~현재) | Q54: 8 | R54: 확정
B55: 42 | C55: 보조강사 | D55: 광량과 입사각에 따른 태양광 발전효율 선형회귀분석 | E55: 가 | F55: 윤남순 | G55: 19760407 | H55: 한국교육협동조합 | I55: 전문강사 | J55: - | K55: 학사 | L55: 경영학 | M55: 메타버스교육지도사2급(22.06.27)방과후공학코딩지도사2급(22.07.01)방과후창의메이커스지도사(22.07.01)COS2급(22.07.02)드른교육지도사(23.06.19)컴퓨팅사고력보드게임지도사(23.06.19)mblock 파이썬자격증(23.06.30) | N55: - | O55: 서울 인천지역 | P55: 인하대.차융합.재능대.마루한.동양대.하이코두.코코아팹디지털새싹캠프(23~현재),초.중.고4차산업및 창의미래수업(22.10~현재), 진로수업(22.12~현재),디지털배움터강사(22.07~12월) | Q55: 8 | R55: 확정
B56: 43 | C56: 주강사 | D56: 광량과 입사각에 따른 태양광 발전효율 선형회귀분석 | E56: 나 | F56: 육동건 | G56: 19850105 | H56: 단국대학교부속소프트웨어고등학교 | I56: 교사 | J56: 단국대학교 | K56: 학사 | L56: 기계공학과, 컴퓨터교육과 | M56: 20110217 | N56: 13 | O56: 서울 인천지역 | P56: 삼성디스플레이 TV디스플레이개발, 모바일디스플레이 개발('11~`15년) 인하대 잡스의 차고캠프 강사(23~현재) | Q56: 8 | R56: 확정
B57: 44 | C57: 주강사 | D57: 광량과 입사각에 따른 태양광 발전효율 선형회귀분석 | E57: 가 | F57: 이진원 | G57: 19780724 | H57: 동산중학교 | I57: 교사 | J57: 인하대학교 교육대학원 | K57: 석사 | L57: AI융합교육 | M57: 2002년2월30일인사 | N57: 19 | O57: 서울 인천지역 | P57: 인하대잡스의 차고 캠프 강사(현재) | Q57: 8 | R57: 확정
B58: 45 | C58: 보조강사 | D58: 광량과 입사각에 따른 태양광 발전효율 선형회귀분석 | E58: 가 | F58: 김혜련 | G58: 19790714 | H58: 프리랜서 강사 | I58: 전문강사 | J58: 재능대학교 | K58: 학사 | L58: 컴퓨터정보과 | M58: 정보처리기사 (2022년 12월) | N58: 4 | O58: 서울 인천지역 | P58: SW미래채움 강사(20~21년) 디지털배움터(22년) 디지털새싹 재능대(22~23년) 디지털새싹 숙명여대(23년) | Q58: 8 | R58: 확정
B59: 46 | C59: 주강사 | D59: 광량과 입사각에 따른 태양광 발전효율 선형회귀분석 | E59: 가 | F59: 홍승권 | G59: 19870120 | H59: 덕적초등학교 | I59: 교사 | J59: 경인교육대학교 | K59: 학사 | L59: 경인교육대학교 대학원 융합교육전공 수료 | M59: 발명교사인증제 2급 2023년9월 | N59: 6 | O59: 서울 인천지역 | P59: 인하대 잡스의 차고캠프 강사(23~현재 | Q59: 8 | R59: 확정
B60: 47 | C60: 보조강사 | D60: 광량과 입사각에 따른 태양광 발전효율 선형회귀분석 | E60: 나 | F60: 홍순기 | G60: 19891103 | H60: 부평고등학교 | I60: 교사 | J60: 인하대학교 교육대학원 | K60: 석사 | L60: AI융합교육 | M60: - | N60: 3 | O60: 서울 인천지역 | P60: 인하대 잡스의 차고캠프 강사(23~현재) '모든교사를위한인천형인공지능교육' 제작 참여 | Q60: 8 | R60: 확정
B61: 48 | C61: 주강사 | D61: 광량과 입사각에 따른 태양광 발전효율 선형회귀분석 | E61: 가 | F61: 서강식 | G61: 19770226 | H61: 간석여자중학교 | I61: 교사 | J61: 인하대학교 교육대학원 | K61: 석사 | L61: AI융합교육 | M61: 정보처리기사(2001.9.11) | N61: 22 | O61: 서울 인천지역 | P61: 인하대 잡스의 차고캠프 강사(23~현재) AIDAP 마스터교원 | Q61: 8 | R61: 확정
B62: 49 | C62: 주강사 | D62: 광량과 입사각에 따른 태양광 발전효율 선형회귀분석 | E62: 가 | F62: 공민수 | G62: 19810601 | H62: 인천금마초등학교 | I62: 교사 | J62: 경인교육대학교 교육전문대학원 | K62: 석사 | L62: 인공지능융합교육과 | M62: 교원자격증 정교사 1급 (14.8.27) / 교원자격증 정교사 2급 (10.2.9) | N62: 16 | O62: 서울 인천지역 | P62: 수상내역 - 2023 과학기술부 장관상 수상 - 2023 교사 에듀톤 1위 수상 - 2023 교육과정 디자인 교육장상 수상 - 2022 스마트 디바이스 활용 공모전 1위 수상 - 2022 교사 에듀톤 3위 수상 활동 - 인공지능 선도학교 컨설팅단 팀장(22~23) - 디지털교육지원단 AI 분과장(22~23) - ChatGPT 인천가이드라인 초등팀장(23) - 인하대 잡스의 차고캠프 강사(23~현재) | Q62: 8 | R62: 확정
B63: 50 | C63: 주강사 | D63: 광량과 입사각에 따른 태양광 발전효율 선형회귀분석 | E63: 가 | F63: 송정희 | G63: 19740413 | H63: 한국교육협동조합 | I63: 전문강사 | J63: 방송통신대학교, 한국전산원 | K63: 학사 | L63: 청소년교육과 ,정보처리학과 | M63: ITQ(2012), DIAT(2012), MOS(2012),SW1급(2015) | N63: 18 | O63: 서울 인천지역 | P63: 컴퓨터학원 강사(1995-1999) 방과후강사(2011~현재) | Q63: 8 | R63: 확정
B64: 51 | C64: 보조강사 | D64: 장애인 접근성 개선 AIOT 연구 개발 프로젝트-내눈을 따라 다니는 인공지능 | E64: 나 | F64: 이혜정 | G64: 19810224 | H64: 한국교육협동조합 | I64: 전문강사 | J64: 국가평생교육원 | K64: 학사 | L64: 아동학 | M64: 코딩지도사1급(22.0916), cos 엔트리 1급(22.08.13), cdt 스크레치 1급(22.11.04), 메타버스 교육지도사 1급(22.11.07), 인공지능 교육지도사1급(23.03.14), 프롬프트 지도사 자격증(23.11.06), 파이썬 전문가 1급(24.01.08) | N64: 4 | O64: 서울 인천지역 | P64: 방과후 창의코딩('23.04~11),디지털배움터('23.04~11),SW4차산업 출강('22.10~현재) | Q64: 8 | R64: 확정
B65: 52 | C65: 보조강사 | D65: 장애인 접근성 개선 AIOT 연구 개발 프로젝트-내눈을 따라 다니는 인공지능 | E65: 가 | F65: 김미선 | G65: 19840823 | H65: 한국교육협동조합 | I65: 전문강사 | J65: 숭의여자대학 | K65: 학사 | L65: 컴퓨터공학 | M65: 실기교사교원자격증(2008.2,20) | N65: 9 | O65: 서울 인천지역 | P65: 성사고등학교 정보교과 강의(2018년) 영종고등학교 정보교과 강의(2021) 인하대 잡스의 차고캠프 강사(23~현재) | Q65: 8 | R65: 확정
B66: 53 | C66: 보조강사 | D66: 장애인 접근성 개선 AIOT 연구 개발 프로젝트-내눈을 따라 다니는 인공지능 | E66: 나 | F66: 황명균 | G66: 19700915 | H66: 한국교육협동조합 | I66: 전문강사 | J66: 유한대학교 기계공학과 졸업 | K66: 기타 | L66: 기계공학과 | M66: 4차산업지도사1급,코딩지도사1급,인공지능지도사1급 | N66: 11 | O66: 서울 인천지역 | P66: 인하대 찹스의 차고캠프(23~현재), 신기초 코딩부 ('17~'19),평촌초 코딩부('18~'20) | Q66: 8 | R66: 확정
B67: 54 | C67: 보조강사 | D67: 장애인 접근성 개선 AIOT 연구 개발 프로젝트-내눈을 따라 다니는 인공지능 | E67: 가 | F67: 조성경 | G67: 19770211 | H67: 프리랜서 강사 | I67: 전문강사 | J67: 대구대학교 | K67: 석사 | L67: 경영학과 | M67: SW코딩2급(23.7.27)/인공지능교육지도사1급(23.11.1) | N67: 2 | O67: 서울 인천지역 | P67: 인하대 디지털 새싹/삼성 SDS코딩교육/ | Q67: 8 | R67: 확정
B68: 55 | C68: 보조강사 | D68: 장애인 접근성 개선 AIOT 연구 개발 프로젝트-내눈을 따라 다니는 인공지능 | E68: 가 | F68: 이유정 | G68: 19700126 | H68: 한국교육협동조합 | I68: 전문강사 | J68: 배화여자대학교 | K68: 기타 | L68: 의상 | M68: 메타버스교육지도사 1급 : 2022.03.10 Autodesk Certified User : 2021.11.12 4차산업혁명교육지도사 1급 : 2021.02.08 초경량비행장치 조종자 : 2019.10.29 무선조종지도자(드론) 2급 : 2017.06.29 코딩지도사 2급 : 2017.06.29 | N68: 7 | O68: 서울 인천지역 | P68: 인하대 잡스의 차고캠프 강사(`23~현재) 송담초등학교-AIoT 피지컬 컴퓨팅 (`21~`23) 디지털 새싹 강사(`23~현재) 인천재능고-생성형 AI를 활용한 앱인벤터 앱만들기, 아두이노(`22~`23) KH정보교육원-유니티 튜터(`23) 게임문화교실 참여, 하인슈타인 참여(`22~`23) 위즈라이브-데이터 분석 과정, 앱 창작 과정 (`20~현재) SSAFY-게임 코딩 과정/로봇 과정 (`21~`22) 용산꿈나무종합타운, 서초청소년도서관, 인천학나래도서관-메타버스 크리에이터 과정(`21~`23) 그 외 다수 | Q68: 8 | R68: 확정
... B138: 125 | C138: 주강사 | D138: 페트병의 모래를 흔들어라 - 에너지 ON | E138: 나 | F138: 백주열 | G138: 19790930 | H138: 경상권학정초등학교 | I138: 교사 | J138: - | K138: 석사 | L138: 초등교육 | M138: 미래교육에 에듀테크를 더하다(한국교총원격연수원) 디지털기반수업혁신,메타버스(경상권시교육청) 애듀테크,SW-AI 선도교원연수(경상권시교육청) | N138: 23 | O138: 경상권 | P138: - | Q138: 8 | R138: 확정
B139: 126 | C139: 주강사 | D139: 페트병의 모래를 흔들어라 - 에너지 ON | E139: 나 | F139: 이부진 | G139: 19800622 | H139: 경상권용계초등학교 | I139: 교사 | J139: - | K139: 석사 | L139: 영재교육 | M139: 교육부 장관상 수상('23.12.28) | N139: 20 | O139: 경상권 | P139: 에듀테크 활용 가이드집 ('23-'24) AI 코스웨어 활용 가이드집('23-'24)2023 KERIS 공모 AI융합 교사연구회 - 생성형 AI 활용 수업 자료 개발 및 적용 | Q139: 8 | R139: 확정
...

Sheet (공통)_교육 인프라 목록
B1: 교육 인프라 목록
B4: 연번 | C4: 프로그램명 | D4: 구분 (시설/장비/교구재) | E4: 시설/장비/교구재명 | F4: 교육시설 정보(집합형일 경우 필수) | M4: 장비 정보 | R4: 교구재 정보
F5: 구분 | G5: 수량 (개) | H5: 시설 정원 | I5: 시설 면적(㎡) | J5: 시설 소재지 | K5: 임차여부 | L5: 괸리주체 | M5: 수량 (개) | N5: 장비 구입/임차처 | O5: 임차여부 | P5: 규격·사양 | Q5: 관리주체 | R5: 저자 또는 개발처 | S5: 수량 (개) | T5: 단가 | U5: 구분 | V5: 규격·사양 | W5: 관리주체
B6: 1 | C6: AI 인터렉티브아트 창작자 | D6: 시설 | E6: 인하대학교 국제학부 322호 | F6: 강의실 | G6: 1 | H6: 108명 | I6: 165㎡ | J6: 인천 미추홀구 | K6: 자체 | L6: 인하대항공우주캠 | M6: 회
B7: 2 | C7: 강화학습 자율주행AI 개발자 (Sim2Real) | D7: 시설 | E7: 인하대학교 항공우주캠퍼스 203호 | F7: 강의실 | G7: 1 | H7: 30명 | I7: 66㎡ | J7: 인천 연수구 | K7: 자체 | L7: 인하대항공우주캠
B8: 4 | C8: AI배달 로봇 엔지니어 | D8: 시설 | E8: 인하대학교 항공우주캠퍼스 206호 | F8: 강의실 | G8: 1 | H8: 30명 | I8: 66㎡ | J8: 인천 연수구 | K8: 자체 | L8: 인하대항공우주캠
B9: 5 | C9: 행정공간 | D9: 시설 | E9: 인하대학교 항공우주캠퍼스 319-A호 | F9: 행정실 | G9: 1 | H9: 10명 | I9: 40㎡ | J9: 인천 연수구 | K9: 자체 | L9: 인하대항공우주캠
B10: 6 | C10: AI 인터렉티브아트 창작자 | D10: 교구재 | E10: 아두이노 | R10: ㈜에스에프에듀 | S10: 21 | T10: 99000 | U10: 아두이노 | W10: 자체
B11: 7 | C11: AI데이터 분석관 | D11: 교구재 | E11: microbit | R11: ㈜에스에프에듀 | S11: 21 | T11: 99000 | U11: microbit | W11: 자체
B12: 8 | C12: 다문화 AI 큐레이터 | D12: 장비 | E12: 노트북 | M12: 20 | N12: 노트북 / 학교 | O12: 자체 | P12: OS : Windows10 64bit | Q12: 자체
B13: ※ 시설, 장비, 교구재 활용 시 관련 견적서 첨부 필수

Sheet 사업운영비 작성방법(작성x)
A1: 엔트리를 활용한 우리 지역 날씨 예측 프로그램 세부 산출내역서
A3: 비목 | B3: 세목 | C3: 세세목 | D3: 관리목 | E3: 산출내역 | N3: 금액 | O3: 비고
E4: 품명 | F4: 금액(공급가액) | G4: 단위 | H4: x | I4: 수량 | J4: 단위 | K4: x | L4: 횟수 | M4: 단위
B5: 사업운영비 | C5: ■ 시설·장비 임차비 | D5: 장비 임차 | E5: LG 그램 노트북 | F5: 60000 | G5: 원 | H5: × | I5: 60 | J5: 대 | K5: × | L5: 6 | M5: 개월 | N5: =F5*I5*L5 -> 21600000 | O5: 1인/1대
D6: 교구 임차 | E6: AI코디니 임차비(범용성) | F6: 360000 | G6: 원 | H6: × | I6: 20 | J6: 대 | K6: x | L6: 6 | M6: 회 | N6: =F6*I6*L6 -> 43200000 | O6: 4인/1대
D7: 교육장·시설 임차 | E7: 000 강의실 | F7: 400000 | G7: 원 | H7: × | I7: 1 | J7: 실 | K7: x | L7: 2 | M7: 회 | N7: =F7*I7*L7 -> 800000 | O7: 20인/1실
C8: ■ 재료구입비 | D8: 교구 구매 | E8: 보드 구입(일회성) | F8: 10000 | G8: 원 | H8: × | I8: 20 | J8: 개 | K8: x | L8: 20 | M8: 회 | N8: =F8*I8*L8 -> 4000000 | O8: 1인/1개
C9: ■ 인쇄·복사·인화· 슬라이드 제작비 | D9: 교재 인쇄·제작·구매 | E9: 0000 교재 구입 | F9: 20000 | G9: 원 | H9: × | I9: 20 | J9: 부 | K9: x | L9: 20 | M9: 회 | N9: =F9*I9*L9 -> 8000000 | O9: 1인/1부
C10: ■ 외부 전문가 기술 활용비 | D10: 강사료 | E10: 주강사 | F10: 300000 | G10: 원 | H10: × | I10: 5 | J10: 인 | K10: x | L10: 20 | M10: 회 | N10: =F10*I10*L10 -> 30000000
D11: 강사료 | E11: 보조강사 | F11: 180000 | G11: 원 | H11: x | I11: 10 | J11: 인 | K11: x | L11: 20 | M11: 회 | N11: =F11*I11*L11 -> 36000000
D12: 강사료 | E12: 교통비(평균 적용) | F12: 30000 | G12: 원 | H12: x | I12: 15 | J12: 인 | K12: x | L12: 20 | M12: 회 | N12: =F12*I12*L12 -> 9000000
D13: 외부 전문가 활용 | E13: 전문가 자문 | F13: 200000 | G13: 원 | H13: × | I13: 5 | J13: 인 | K13: x | L13: 1 | M13: 회 | N13: =F13*I13*L13 -> 1000000
C14: ■ 일용직활용비 | D14: 단기근로자 활용 | E14: 안전관리요원 | F14: 40000 | G14: 원 | H14: x | I14: 1 | J14: 인 | K14: x | L14: 20 | M14: 회 | N14: =F14*I14*L14 -> 800000
C15: ■ 회의비 | D15: 교육생 식·다과비 | E15: 다과 제공 | F15: 10000 | G15: 원 | H15: x | I15: 20 | J15: 인 | K15: x | L15: 20 | M15: 회 | N15: =F15*I15*L15 -> 4000000
C16: ■ 제세공과·수수료·공공요금 | D16: 보험료 | E16: 보험명 | F16: 2000 | G16: 원 | H16: x | I16: 20 | J16: 인 | K16: x | L16: 15 | M16: 회 | N16: =F16*I16*L16 -> 600000
C17: ■ 우편요금·택배비 | D17: 운송비 | E17: 장비 운송 | F17: 30000 | G17: 원 | H17: x | I17: 60 | J17: 대 | K17: x | L17: 20 | M17: 회 | N17: =F17*I17*L17 -> 36000000
C18: ■ 기타 경비 | D18: 인원 수송 | E18: 차량 렌트 | F18: 80000 | G18: 원 | H18: x | I18: 1 | J18: 대 | K18: x | L18: 10 | M18: 회 | N18: =F18*I18*L18 -> 800000
A19: 총계(3=(1)+(2)) | N19: =SUM(N5:N18) -> 195800000
A21: □ 작성가이드(※ 작성 전 안내 사항 반드시 확인 후 제출합니다) | U21: `
A22: [프로그램 운영비 편성 시 고려사항] 1. 실 작성 시 모든 폰트는 검은색으로 변경하여 작성 2. 제안 프로그램 수에 맞게 각각의 운영비 산출 필요(예. 제안프로그램 6종→세부 산출내역서 6부(시트) 필요) 3. 매입부가세가 발생하는 항목은 공급가액과 매입부가세 합산 금액 작성, 강사료, 보험료 등 매입부가세와 관련없는 항목은 실 집행금액 작성 4. 장비 및 교구재, 교육장 등 기준인원이 있는 항목은 각 항목별 비고란에 1대(개,실,부 등)당 기준인원수 필수 기입 5. 장비 및 교구재, 교육장 등의 금액(공급가액)은 실제 1대(개,실,부 등)당 임차 또는 구매 금액으로, 수량은 실 갯수 기입 (산출내역 수량 및 횟수 단위에 사람 수(人) 기준 단위로 변경 불가) 6. 단위는 가급적 변경을 지양하고, 불가피하게 변경하더라도 1식 등의 모호한 표현 금지 7. 프로그램별 산출이 어려운 행사, 강사 연수 비용 등은 총 필요 예산을 제안 프로그램별 적절하게 분배하여 기입 가능 8. 프로그램별 실제 운영에 필요한 비용으로 계상하되 전체 제안프로그램 운영비 및 사업관리비, 간접비의 합계가 신청유형별(새싹A/B) 최대 예산을 넘지않도록 주의

Sheet 사업관리비 및 간접비 작성방법(작성x)
A1: 사업관리비 및 간접비 작성 예시('총 사업비 산출' 시트)
A3: 비목 | B3: 세목 | C3: 세세목 | D3: 관리목 | E3: 산출내역 | N3: 금액 | O3: 구성비
E4: 품명 | F4: 금액(공급가액) | G4: 단위 | H4: x | I4: 수량 | J4: 단위 | K4: x | L4: 횟수 | M4: 단위
A5: 직접비 | B5: 사업운영비 소계(1) | N5: 814660000
B6: 사업관리비 | C6: ■ 내부 인건비 | D6: 참여 인력 인건비 | E6: 행정연구원(강혜영) | G6: 원 | H6: × | I6: 1 | J6: (참여율) | K6: x | L6: 8 | M6: 회 | N6: =F6*I6*L6 -> 0 | O6: =N19/N20 -> 0
E7: 행정연구원(이상원) | G7: 원 | H7: × | I7: 1 | J7: (참여율) | K7: x | L7: 8 | M7: 개월 | N7: =F7*I7*L7 -> 0
E8: 학생연구원(정의손) | G8: 원 | H8: × | I8: 1 | J8: (참여율) | K8: x | L8: 8 | M8: 개월 | N8: =F8*I8*L8 -> 0
E9: 학생연구원(김현일) | G9: 원 | H9: × | I9: 1 | J9: (참여율) | K9: x | L9: 8 | M9: 개월 | N9: =F9*I9*L9 -> 0
E10: 보조연구원(학부) | G10: 원 | H10: × | I10: 0.5 | J10: (참여율) | K10: x | L10: 8 | M10: 개월 | N10: =F10*I10*L10 -> 0
E11: 보조연구원(학부) | G11: 원 | H11: × | I11: 0.5 | J11: (참여율) | K11: x | L11: 8 | M11: 개월 | N11: =F11*I11*L11 -> 0
D12: 참여 인력 사업 수당 | E12: 미지급인력 | G12: 원 | H12: × | I12: 1 | J12: 인 | K12: x | L12: 8 | M12: 개월 | N12: =F12*I12*L12 -> 0
E13: 미지급인력 | G13: 원 | H13: × | I13: 1 | J13: 인 | K13: x | L13: 8 | M13: 개월 | N13: =F13*I13*L13 -> 0
C14: ■ 회의비 | D14: 회의 식·다과비 | E14: 회의비 | G14: 원 | H14: x | I14: 20 | J14: 인 | K14: x | L14: 80 | M14: 회 | N14: =F14*I14*L14 -> 0
C15: ■ 출장비 | D15: 국내 출장 여비 | E15: 현장 운영 출장 | G15: 원 | H15: x | I15: 4 | J15: 인 | K15: x | L15: 20 | M15: 회 | N15: =F15*I15*L15 -> 0
C16: ■ 인쇄·복사·인화· 슬라이드 제작비 | D16: 홍보물 인쇄·제작 | E16: 현수막, 리플렛 | G16: 원 | H16: × | I16: 10 | J16: 인 | K16: x | L16: 6 | M16: 회 | N16: =F16*I16*L16 -> 0
C17: ■ 제세공과·수수료·공공요금 | D17: 정산수수료 | E17: 정산수수료 | G17: 원 | H17: × | I17: 1 | J17: 건 | K17: x | L17: 1 | M17: 회 | N17: =F17*I17*L17 -> 0
C18: ■ 사무용품비 | D18: 사무용품 | E18: 문구류 | G18: 원 | K18: x | L18: 30 | M18: 회 | N18: =F18*L18 -> 0
B19: 사업관리비 소계(2) | N19: =SUM(N6:N18) -> 0
A20: 직접비 소계(3) | N20: =N5+N19 -> 814660000
A21: 간접비 | B21: 간접비 | C21: ■ 지원인력 인건비 | D21: 지원인력 인건비 | E21: 지원인력 A | G21: 원 | H21: x | I21: 1 | J21: 인 | K21: x | L21: 8 | M21: 개월 | N21: =F21*I21*L21 -> 0 | O21: =N27/N20 -> 0
E22: 지원인력 A | G22: 원 | H22: x | I22: 1 | J22: 인 | K22: x | L22: 8 | M22: 개월 | N22: =F22*I22*L22 -> 0
C23: ■ 기관 공통경비 | D23: 기관공통비 | E23: 기관공통비 | G23: 원 | H23: x | I23: 1 | J23: 건 | K23: x | L23: 8 | M23: 개월 | N23: =F23*I23*L23 -> 0
C24: ■ 장비·시설 구축 및 운영비 | D24: 장비 구축비 | E24: 보관함(서랍) | G24: 원 | H24: x | I24: 2 | J24: 대 | K24: x | L24: 2 | M24: 회 | N24: =F24*I24*L24 -> 0
D25: 비품 구입 | E25: A4용지(세트) | G25: 원 | H25: x | I25: 2 | J25: 세트 | K25: x | L25: 2 | M25: 회 | N25: =F25*I25*L25 -> 0
D26: 공공요금 | E26: 수도, 전기료 등 요금 | G26: 원 | H26: x | I26: 3 | J26: 건 | K26: x | L26: 4 | M26: 개월 | N26: =F26*I26*L26 -> 0
A27: 간접비 소계(4) | N27: =SUM(N21:N26) -> 0
A28: 총계 (5)=(3)+(4) | N28: =N20+N27 -> 814660000
A30: □ 작성가이드(※ 작성 전 안내 사항 반드시 확인 후 제출합니다) | U30: `
A31: [사업관리비 및 간접비 편성 시 고려사항] 1. 실 작성 시 모든 폰트는 검은색으로 변경하여 작성 2. 사업관리비 및 간접비는 '총 사업비 산출' 시트에만 작성 3. 매입부가세가 발생하는 항목은 공급가액과 매입부가세 합산 금액 작성, 강사료, 보험료 등 매입부가세와 관련없는 항목은 실 집행금액 작성 4. 인건비 내 초과근무수당 계상 가능하나 참여율 기준으로 계상해야 함(예. 참여율 50%라면 지급 필요 초과근무수당에서 50%까지 책정 가능) 5. 직접비와 간접비로 구분하여 편성하되, 간접비는 직접비(사업운영비+사업관리비)의 5% 이내로 편성('구성비' 확인 필) 6. 사업관리비 합계는 직접비(사업운영비+사업관리비)의 15% 이내로 편성('구성비' 확인 필) 7. 단위는 가급적 변경을 지양하고, 불가피하게 변경하더라도 1식 등의 모호한 표현 금지 8. 사업수당은 미지급인건비의 20%이하 준수('금액' 열에 해당 비율 반영하여 산출, 현재는 0.2(20%)로 반영되어 있음) 9. 정산수수료 책정 필수(공급가액 150만원, 향후 정확한 금액 안내 및 일괄 사업비 변경 요청 예정)

Sheet A프로그램
A1: (AI 인터렉티브아트 창작자) 프로그램 세부 산출내역서
A3: 비목 | B3: 세목 | C3: 세세목 | D3: 관리목 | E3: 산출내역 | N3: 금액 | O3: 비고
E4: 품명 | F4: 금액(공급가액) | G4: 단위 | H4: x | I4: 수량 | J4: 단위 | K4: x | L4: 횟수 | M4: 단위
B5: 사업운영비 | C5: ■ 시설·장비 임차비 | D5: 장비임차 | E5: 노트북 | F5: 40000 | G5: 원 | H5: × | I5: 9 | J5: 대 | K5: × | L5: 8 | M5: 개월 | N5: =F5*I5*L5 -> 2880000
D6: 장비임차 | E6: ZOOM 1.7 | F6: 30000 | G6: 원 | H6: × | I6: 1 | J6: 대 | K6: x | L6: 17 | M6: 회 | N6: =F6*I6*L6 -> 510000
G7: 원 | H7: × | J7: 실 | K7: x | M7: 회 | N7: =F7*I7*L7 -> 0
C8: ■ 재료구입비 | D8: 교구 구매(교구, 범용성) | E8: 무선 카메라 | F8: 55000 | G8: 원 | H8: × | I8: 186 | J8: 개 | K8: x | L8: 1 | M8: 회 | N8: =F8*I8*L8 -> 10230000
D9: 교구 구매(일회성) | E9: 창산용 문구류 | F9: 5751 | G9: 원 | H9: × | I9: 20 | J9: 개 | K9: x | L9: 28 | M9: 회 | N9: =F9*I9*L9 -> 3220560
C10: ■ 인쇄·복사·인화· 슬라이드 제작비 | G10: 원 | H10: × | J10: 부 | K10: x | M10: 회 | N10: =F10*I10*L10 -> 0
N11: =F11*I11*L11 -> 0
C12: ■ 외부 전문가 기술 활용비 | D12: 강사료 | E12: 주강사료 | F12: 100000 | G12: 원 | H12: × | I12: 8 | J12: 인 | K12: x | L12: 36 | M12: 회 | N12: =F12*I12*L12 -> 28800000 | Q12: 75000 | R12: 8 | S12: 49 | T12: =Q12*S12*R12 -> 29400000
D13: 강사료 | E13: 보조강사료 | F13: 60000 | G13: 원 | H13: x | I13: 8 | J13: 인 | K13: x | L13: 36 | M13: 회 | N13: =F13*I13*L13 -> 17280000 | Q13: 45000 | R13: 8 | S13: 49 | T13: =Q13*S13*R13 -> 17640000
D14: 외부전문가 활용 | E14: 자문 및 강사교육용 강사료 | F14: 100000 | G14: 원 | H14: x | I14: 1 | J14: 인 | K14: x | L14: 40 | M14: 회 | N14: =F14*I14*L14 -> 4000000
D15: 외부전문가 활용 | E15: 교육 프로그램 고도화 | F15: 250000 | G15: 원 | H15: × | I15: 1 | J15: 인 | K15: x | L15: 8 | M15: 회 | N15: =F15*I15*L15 -> 2000000
D16: 교통비 | E16: 교통비 | F16: 10000 | G16: 원 | H16: × | I16: 1 | J16: 인 | K16: x | L16: 28 | M16: 회 | N16: =F16*I16*L16 -> 280000
C17: ■ 일용직활용비 | D17: 단기근로자 활용 | E17: 안전관리요원 | F17: 20000 | G17: 원 | H17: x | I17: 8 | J17: 인 | K17: x | L17: 22 | M17: 회 | N17: =F17*I17*L17 -> 3520000
E18: 진행요원 | F18: 20000 | G18: 원 | H18: x | I18: 8 | J18: 인 | K18: x | L18: 22 | M18: 회 | N18: =F18*I18*L18 -> 3520000
C19: ■ 회의비 | D19: 행사 식다과비 | E19: 성과공유회, 강사교육 식비/임차료 | F19: 25000 | G19: 원 | H19: x | I19: 20 | J19: 인 | K19: x | L19: 1 | M19: 회 | N19: =F19*I19*L19 -> 500000
D20: 교육생 식다과비 | E20: 강사. 학생 식비, 다과비 | F20: 10000 | G20: 원 | H20: x | I20: 22 | J20: 인 | K20: x | L20: 58 | M20: 회 | N20: =F20*I20*L20 -> 12760000
C21: ■ 제세공과·수수료·공공요금 | D21: 보험료 | E21: 보험료 | F21: 500 | G21: 원 | H21: x | I21: 20 | J21: 인 | K21: x | L21: 27 | M21: 회 | N21: =F21*I21*L21 -> 270000
N22: =F22*I22*L22 -> 0
C23: ■ 우편요금·택배비 | D23: 운송 비용 | E23: 택배비(교구, 노트북 등) | F23: 10000 | G23: 원 | H23: x | I23: 32 | J23: 반 | K23: x | L23: 2 | M23: 회 | N23: =F23*I23*L23 -> 640000
N24: =F24*I24*L24 -> 0
C25: ■ 기타 경비 | N25: =F25*I25*L25 -> 0
N26: =F26*I26*L26 -> 0
A27: 총계 | N27: =SUM(N5:N26) -> 90410560
A29: □ 작성가이드(※ 작성 전 안내 사항 반드시 확인 후 제출합니다)
A30: [프로그램 운영비 편성 시 고려사항] 1. 실 작성 시 모든 폰트는 검은색으로 변경하여 작성 2. 제안 프로그램 수에 맞게 각각의 운영비 산출 필요(예. 제안프로그램 6종→세부 산출내역서 6부(시트) 필요) 3. 매입부가세가 발생하는 항목은 공급가액 기준으로 작성, 강사료, 보험료 등 매입부가세와 관련없는 항목은 실 집행금액 작성 4. 장비 및 교구재, 교육장 등 기준인원이 있는 항목은 각 항목별 비고란에 1대(개,실,부 등)당 기준인원수 필수 기입 5. 장비 및 교구재, 교육장 등의 금액(공급가액)은 실제 1대(개,실,부 등)당 임차 또는 구매 금액으로, 수량은 실 갯수 기입 (산출내역 수량 및 횟수 단위에 사람 수(人) 기준 단위로 변경 불가) 6. 단위는 가급적 변경을 지양하고, 불가피하게 변경하더라도 1식 등의 모호한 표현 금지 7. 프로그램별 산출이 어려운 행사, 강사 연수 비용 등은 총 필요 예산을 제안 프로그램별 적절하게 분배하여 기입 가능 8. 프로그램별 실제 운영에 필요한 비용으로 계상하되 전체 제안프로그램 운영비 및 사업관리비, 간접비의 합계가 신청유형별(새싹A/B) 최대 예산을 넘지않도록 주의

Sheet B프로그램
A1: (AI배달 로봇 엔지니어) 프로그램 세부 산출내역서
A3: 비목 | B3: 세목 | C3: 세세목 | D3: 관리목 | E3: 산출내역 | N3: 금액 | O3: 비고
E4: 품명 | F4: 금액(공급가액) | G4: 단위 | H4: x | I4: 수량 | J4: 단위 | K4: x | L4: 횟수 | M4: 단위
B5: 사업운영비 | C5: ■ 시설·장비 임차비 | D5: 장비임차 | E5: 노트북 | F5: 40000 | G5: 원 | H5: × | I5: 9 | J5: 대 | K5: × | L5: 8 | M5: 개월 | N5: =F5*I5*L5 -> 2880000
G6: 원 | H6: × | J6: 대 | K6: x | M6: 회 | N6: =F6*I6*L6 -> 0
G7: 원 | H7: × | J7: 실 | K7: x | M7: 회 | N7: =F7*I7*L7 -> 0
C8: ■ 재료구입비 | D8: 교구 구매(교구, 범용성) | E8: 오토바이, 주행코스, 배터리 | F8: 298000 | G8: 원 | H8: × | I8: 201 | J8: 개 | K8: x | L8: 1 | M8: 회 | N8: =F8*I8*L8 -> 59898000
D9: 교구 구매(일회성) | E9: 창산용 문구류 | F9: 5751 | G9: 원 | H9: × | I9: 20 | J9: 개 | K9: x | L9: 28 | M9: 회 | N9: =F9*I9*L9 -> 3220560
C10: ■ 인쇄·복사·인화· 슬라이드 제작비 | G10: 원 | H10: × | J10: 부 | K10: x | M10: 회 | N10: =F10*I10*L10 -> 0
N11: =F11*I11*L11 -> 0
C12: ■ 외부 전문가 기술 활용비 | D12: 강사료 | E12: 주강사료 | F12: 75000 | G12: 원 | H12: × | I12: 8 | J12: 인 | K12: x | L12: 40 | M12: 회 | N12: =F12*I12*L12 -> 24000000
D13: 강사료 | E13: 보조강사료 | F13: 45000 | G13: 원 | H13: x | I13: 8 | J13: 인 | K13: x | L13: 40 | M13: 회 | N13: =F13*I13*L13 -> 14400000
D14: 외부전문가 활용 | E14: 자문 및 강사교육용 강사료 | F14: 100000 | G14: 원 | H14: x | I14: 1 | J14: 인 | K14: x | L14: 40 | M14: 회 | N14: =F14*I14*L14 -> 4000000
D15: 외부전문가 활용 | E15: 교육 프로그램 고도화 | F15: 250000 | G15: 원 | H15: × | I15: 1 | J15: 인 | K15: x | L15: 8 | M15: 회 | N15: =F15*I15*L15 -> 2000000
D16: 교통비 | E16: 교통비 | F16: 10000 | G16: 원 | H16: × | I16: 1 | J16: 인 | K16: x | L16: 28 | M16: 회 | N16: =F16*I16*L16 -> 280000
C17: ■ 일용직활용비 | D17: 단기근로자 활용 | E17: 안전관리요원 | F17: 20000 | G17: 원 | H17: x | I17: 8 | J17: 인 | K17: x | L17: 22 | M17: 회 | N17: =F17*I17*L17 -> 3520000
E18: 진행요원 | F18: 20000 | G18: 원 | H18: x | I18: 8 | J18: 인 | K18: x | L18: 22 | M18: 회 | N18: =F18*I18*L18 -> 3520000
C19: ■ 회의비 | D19: 행사 식다과비 | E19: 성과공유회, 강사교육 식비/임차료 | F19: 25000 | G19: 원 | H19: x | I19: 20 | J19: 인 | K19: x | L19: 1 | M19: 회 | N19: =F19*I19*L19 -> 500000
D20: 교육생 식다과비 | E20: 강사. 학생 식비, 다과비 | F20: 10000 | G20: 원 | H20: x | I20: 22 | J20: 인 | K20: x | L20: 58 | M20: 회 | N20: =F20*I20*L20 -> 12760000
C21: ■ 제세공과·수수료·공공요금 | D21: 보험료 | E21: 보험료 | F21: 500 | G21: 원 | H21: x | I21: 20 | J21: 인 | K21: x | L21: 27 | M21: 회 | N21: =F21*I21*L21 -> 270000
N22: =F22*I22*L22 -> 0
C23: ■ 우편요금·택배비 | D23: 운송 비용 | E23: 택배비(교구, 노트북 등) | F23: 10000 | G23: 원 | H23: x | I23: 32 | J23: 반 | K23: x | L23: 2 | M23: 회 | N23: =F23*I23*L23 -> 640000
N24: =F24*I24*L24 -> 0
C25: ■ 기타 경비 | N25: =F25*I25*L25 -> 0
A26: 총계 | N26: =SUM(N5:N25) -> 131888560
A28: □ 작성가이드(※ 작성 전 안내 사항 반드시 확인 후 제출합니다)
A29: [프로그램 운영비 편성 시 고려사항] 1. 실 작성 시 모든 폰트는 검은색으로 변경하여 작성 2. 제안 프로그램 수에 맞게 각각의 운영비 산출 필요(예. 제안프로그램 6종→세부 산출내역서 6부(시트) 필요) 3. 매입부가세가 발생하는 항목은 공급가액 기준으로 작성, 강사료, 보험료 등 매입부가세와 관련없는 항목은 실 집행금액 작성 4. 장비 및 교구재, 교육장 등 기준인원이 있는 항목은 각 항목별 비고란에 1대(개,실,부 등)당 기준인원수 필수 기입 5. 장비 및 교구재, 교육장 등의 금액(공급가액)은 실제 1대(개,실,부 등)당 임차 또는 구매 금액으로, 수량은 실 갯수 기입 (산출내역 수량 및 횟수 단위에 사람 수(人) 기준 단위로 변경 불가) 6. 단위는 가급적 변경을 지양하고, 불가피하게 변경하더라도 1식 등의 모호한 표현 금지 7. 프로그램별 산출이 어려운 행사, 강사 연수 비용 등은 총 필요 예산을 제안 프로그램별 적절하게 분배하여 기입 가능 8. 프로그램별 실제 운영에 필요한 비용으로 계상하되 전체 제안프로그램 운영비 및 사업관리비, 간접비의 합계가 신청유형별(새싹A/B) 최대 예산을 넘지않도록 주의

Sheet C프로그램
A1: (다문화 AI 큐레이터 ) 프로그램 세부 산출내역서
A3: 비목 | B3: 세목 | C3: 세세목 | D3: 관리목 | E3: 산출내역 | N3: 금액 | O3: 비고
E4: 품명 | F4: 금액(공급가액) | G4: 단위 | H4: x | I4: 수량 | J4: 단위 | K4: x | L4: 횟수 | M4: 단위
B5: 사업운영비 | C5: ■ 시설·장비 임차비 | D5: 장비임차 | E5: 노트북 | F5: 40000 | G5: 원 | H5: × | I5: 9 | J5: 대 | K5: × | L5: 8 | M5: 개월 | N5: =F5*I5*L5 -> 2880000
G6: 원 | H6: × | J6: 대 | K6: x | M6: 회 | N6: =F6*I6*L6 -> 0
G7: 원 | H7: × | J7: 실 | K7: x | M7: 회 | N7: =F7*I7*L7 -> 0
C8: ■ 재료구입비 | D8: 교구 구매(교구, 범용성) | E8: 리치보드, 디스플레이류(4종) | F8: 77000 | G8: 원 | H8: × | I8: 169 | J8: 개 | K8: x | L8: 1 | M8: 회 | N8: =F8*I8*L8 -> 13013000
D9: 교구 구매(일회성) | E9: 창산용 문구류 | F9: 5751 | G9: 원 | H9: × | I9: 20 | J9: 개 | K9: x | L9: 28 | M9: 회 | N9: =F9*I9*L9 -> 3220560
C10: ■ 인쇄·복사·인화· 슬라이드 제작비 | G10: 원 | H10: × | J10: 부 | K10: x | M10: 회 | N10: =F10*I10*L10 -> 0
N11: =F11*I11*L11 -> 0
C12: ■ 외부 전문가 기술 활용비 | D12: 강사료 | E12: 주강사료 | F12: 100000 | G12: 원 | H12: × | I12: 8 | J12: 인 | K12: x | L12: 36 | M12: 회 | N12: =F12*I12*L12 -> 28800000
D13: 강사료 | E13: 보조강사료 | F13: 60000 | G13: 원 | H13: x | I13: 8 | J13: 인 | K13: x | L13: 36 | M13: 회 | N13: =F13*I13*L13 -> 17280000
D14: 외부전문가 활용 | E14: 자문 및 강사교육용 강사료 | F14: 100000 | G14: 원 | H14: x | I14: 1 | J14: 인 | K14: x | L14: 40 | M14: 회 | N14: =F14*I14*L14 -> 4000000
D15: 외부전문가 활용 | E15: 교육 프로그램 고도화 | F15: 250000 | G15: 원 | H15: × | I15: 1 | J15: 인 | K15: x | L15: 8 | M15: 회 | N15: =F15*I15*L15 -> 2000000
D16: 교통비 | E16: 교통비 | F16: 10000 | G16: 원 | H16: × | I16: 1 | J16: 인 | K16: x | L16: 28 | M16: 회 | N16: =F16*I16*L16 -> 280000
C17: ■ 일용직활용비 | D17: 단기근로자 활용 | E17: 안전관리요원 | F17: 20000 | G17: 원 | H17: x | I17: 8 | J17: 인 | K17: x | L17: 22 | M17: 회 | N17: =F17*I17*L17 -> 3520000
E18: 진행요원 | F18: 20000 | G18: 원 | H18: x | I18: 8 | J18: 인 | K18: x | L18: 22 | M18: 회 | N18: =F18*I18*L18 -> 3520000
C19: ■ 회의비 | D19: 행사 식다과비 | E19: 성과공유회, 강사교육 식비/임차료 | F19: 25000 | G19: 원 | H19: x | I19: 40 | J19: 인 | K19: x | L19: 1 | M19: 회 | N19: =F19*I19*L19 -> 1000000
D20: 교육생 식다과비 | E20: 강사. 학생 식비, 다과비 | F20: 10000 | G20: 원 | H20: x | I20: 22 | J20: 인 | K20: x | L20: 58 | M20: 회 | N20: =F20*I20*L20 -> 12760000
C21: ■ 제세공과·수수료·공공요금 | D21: 보험료 | E21: 보험료 | F21: 500 | G21: 원 | H21: x | I21: 20 | J21: 인 | K21: x | L21: 27 | M21: 회 | N21: =F21*I21*L21 -> 270000
N22: =F22*I22*L22 -> 0
C23: ■ 우편요금·택배비 | D23: 운송 비용 | E23: 택배비(교구, 노트북 등) | F23: 10000 | G23: 원 | H23: x | I23: 32 | J23: 반 | K23: x | L23: 3 | M23: 회 | N23: =F23*I23*L23 -> 960000
N24: =F24*I24*L24 -> 0
C25: ■ 기타 경비 | N25: =F25*I25*L25 -> 0
A26: 총계 | N26: =SUM(N5:N25) -> 93503560
A28: □ 작성가이드(※ 작성 전 안내 사항 반드시 확인 후 제출합니다)
A29: [프로그램 운영비 편성 시 고려사항] 1. 실 작성 시 모든 폰트는 검은색으로 변경하여 작성 2. 제안 프로그램 수에 맞게 각각의 운영비 산출 필요(예. 제안프로그램 6종→세부 산출내역서 6부(시트) 필요) 3. 매입부가세가 발생하는 항목은 공급가액 기준으로 작성, 강사료, 보험료 등 매입부가세와 관련없는 항목은 실 집행금액 작성 4. 장비 및 교구재, 교육장 등 기준인원이 있는 항목은 각 항목별 비고란에 1대(개,실,부 등)당 기준인원수 필수 기입 5. 장비 및 교구재, 교육장 등의 금액(공급가액)은 실제 1대(개,실,부 등)당 임차 또는 구매 금액으로, 수량은 실 갯수 기입 (산출내역 수량 및 횟수 단위에 사람 수(人) 기준 단위로 변경 불가) 6. 단위는 가급적 변경을 지양하고, 불가피하게 변경하더라도 1식 등의 모호한 표현 금지 7. 프로그램별 산출이 어려운 행사, 강사 연수 비용 등은 총 필요 예산을 제안 프로그램별 적절하게 분배하여 기입 가능 8. 프로그램별 실제 운영에 필요한 비용으로 계상하되 전체 제안프로그램 운영비 및 사업관리비, 간접비의 합계가 신청유형별(새싹A/B) 최대 예산을 넘지않도록 주의

Sheet D프로그램
A1: (재난안전 AI로봇 운용관) 프로그램 세부 산출내역서
A3: 비목 | B3: 세목 | C3: 세세목 | D3: 관리목 | E3: 산출내역 | N3: 금액 | O3: 비고
E4: 품명 | F4: 금액(공급가액) | G4: 단위 | H4: x | I4: 수량 | J4: 단위 | K4: x | L4: 횟수 | M4: 단위
B5: 사업운영비 | C5: ■ 시설·장비 임차비 | D5: 장비임차 | E5: 노트북 | F5: 40000 | G5: 원 | H5: × | I5: 9 | J5: 대 | K5: × | L5: 8 | M5: 개월 | N5: =F5*I5*L5 -> 2880000
G6: 원 | H6: × | J6: 대 | K6: x | M6: 회 | N6: =F6*I6*L6 -> 0
G7: 원 | H7: × | J7: 실 | K7: x | M7: 회 | N7: =F7*I7*L7 -> 0
C8: ■ 재료구입비 | D8: 교구 구매(교구, 범용성) | E8: 캐터필러, 무선캠, 집게, 배터리 | F8: 298000 | G8: 원 | H8: × | I8: 218 | J8: 개 | K8: x | L8: 1 | M8: 회 | N8: =F8*I8*L8 -> 64964000
D9: 교구 구매(일회성) | E9: 창산용 문구류 | F9: 5751 | G9: 원 | H9: × | I9: 20 | J9: 개 | K9: x | L9: 28 | M9: 회 | N9: =F9*I9*L9 -> 3220560
C10: ■ 인쇄·복사·인화· 슬라이드 제작비 | G10: 원 | H10: × | J10: 부 | K10: x | M10: 회 | N10: =F10*I10*L10 -> 0
N11: =F11*I11*L11 -> 0
C12: ■ 외부 전문가 기술 활용비 | D12: 강사료 | E12: 주강사료 | F12: 100000 | G12: 원 | H12: × | I12: 8 | J12: 인 | K12: x | L12: 36 | M12: 회 | N12: =F12*I12*L12 -> 28800000
D13: 강사료 | E13: 보조강사료 | F13: 60000 | G13: 원 | H13: x | I13: 8 | J13: 인 | K13: x | L13: 36 | M13: 회 | N13: =F13*I13*L13 -> 17280000
D14: 외부전문가 활용 | E14: 자문 및 강사교육용 강사료 | F14: 100000 | G14: 원 | H14: x | I14: 1 | J14: 인 | K14: x | L14: 40 | M14: 회 | N14: =F14*I14*L14 -> 4000000
D15: 외부전문가 활용 | E15: 교육 프로그램 고도화 | F15: 250000 | G15: 원 | H15: × | I15: 1 | J15: 인 | K15: x | L15: 8 | M15: 회 | N15: =F15*I15*L15 -> 2000000
D16: 교통비 | E16: 교통비 | F16: 10000 | G16: 원 | H16: × | I16: 1 | J16: 인 | K16: x | L16: 28 | M16: 회 | N16: =F16*I16*L16 -> 280000
C17: ■ 일용직활용비 | D17: 단기근로자 활용 | E17: 안전관리요원 | F17: 20000 | G17: 원 | H17: x | I17: 8 | J17: 인 | K17: x | L17: 22 | M17: 회 | N17: =F17*I17*L17 -> 3520000
E18: 진행요원 | F18: 20000 | G18: 원 | H18: x | I18: 8 | J18: 인 | K18: x | L18: 22 | M18: 회 | N18: =F18*I18*L18 -> 3520000
C19: ■ 회의비 | D19: 행사 식다과비 | E19: 성과공유회, 강사교육 식비/임차료 | F19: 25000 | G19: 원 | H19: x | I19: 40 | J19: 인 | K19: x | L19: 1 | M19: 회 | N19: =F19*I19*L19 -> 1000000
D20: 교육생 식다과비 | E20: 강사. 학생 식비, 다과비 | F20: 10000 | G20: 원 | H20: x | I20: 22 | J20: 인 | K20: x | L20: 58 | M20: 회 | N20: =F20*I20*L20 -> 12760000
C21: ■ 제세공과·수수료·공공요금 | D21: 보험료 | E21: 보험료 | F21: 500 | G21: 원 | H21: x | I21: 20 | J21: 인 | K21: x | L21: 27 | M21: 회 | N21: =F21*I21*L21 -> 270000
N22: =F22*I22*L22 -> 0
C23: ■ 우편요금·택배비 | D23: 운송 비용 | E23: 택배비(교구, 노트북 등) | F23: 10000 | G23: 원 | H23: x | I23: 32 | J23: 반 | K23: x | L23: 3 | M23: 회 | N23: =F23*I23*L23 -> 960000
N24: =F24*I24*L24 -> 0
C25: ■ 기타 경비 | N25: =F25*I25*L25 -> 0
A26: 총계 | N26: =SUM(N5:N25) -> 145454560
A28: □ 작성가이드(※ 작성 전 안내 사항 반드시 확인 후 제출합니다) | U28: `
A29: [프로그램 운영비 편성 시 고려사항] 1. 실 작성 시 모든 폰트는 검은색으로 변경하여 작성 2. 제안 프로그램 수에 맞게 각각의 운영비 산출 필요(예. 제안프로그램 6종→세부 산출내역서 6부(시트) 필요) 3. 매입부가세가 발생하는 항목은 공급가액 기준으로 작성, 강사료, 보험료 등 매입부가세와 관련없는 항목은 실 집행금액 작성 4. 장비 및 교구재, 교육장 등 기준인원이 있는 항목은 각 항목별 비고란에 1대(개,실,부 등)당 기준인원수 필수 기입 5. 장비 및 교구재, 교육장 등의 금액(공급가액)은 실제 1대(개,실,부 등)당 임차 또는 구매 금액으로, 수량은 실 갯수 기입 (산출내역 수량 및 횟수 단위에 사람 수(人) 기준 단위로 변경 불가) 6. 단위는 가급적 변경을 지양하고, 불가피하게 변경하더라도 1식 등의 모호한 표현 금지 7. 프로그램별 산출이 어려운 행사, 강사 연수 비용 등은 총 필요 예산을 제안 프로그램별 적절하게 분배하여 기입 가능 8. 프로그램별 실제 운영에 필요한 비용으로 계상하되 전체 제안프로그램 운영비 및 사업관리비, 간접비의 합계가 신청유형별(새싹A/B) 최대 예산을 넘지않도록 주의

Sheet E프로그램
A1: (AI데이터 분석관 ) 프로그램 세부 산출내역서
A3: 비목 | B3: 세목 | C3: 세세목 | D3: 관리목 | E3: 산출내역 | N3: 금액 | O3: 비고
E4: 품명 | F4: 금액(공급가액) | G4: 단위 | H4: x | I4: 수량 | J4: 단위 | K4: x | L4: 횟수 | M4: 단위
B5: 사업운영비 | C5: ■ 시설·장비 임차비 | D5: 장비임차 | E5: 노트북 | F5: 40000 | G5: 원 | H5: × | I5: 9 | J5: 대 | K5: × | L5: 8 | M5: 개월 | N5: =F5*I5*L5 -> 2880000
D6: 장비임차 | E6: 캔바5 | F6: 230000 | G6: 원 | H6: × | I6: 1 | J6: 개 | K6: x | L6: 1 | M6: 회 | N6: =F6*I6*L6 -> 230000
G7: 원 | H7: × | J7: 실 | K7: x | M7: 회 | N7: =F7*I7*L7 -> 0
C8: ■ 재료구입비 | D8: 교구 구매(교구, 범용성) | E8: 리치보드, 센서류(5종) | F8: 77000 | G8: 원 | H8: × | I8: 175 | J8: 개 | K8: x | L8: 1 | M8: 회 | N8: =F8*I8*L8 -> 13475000
D9: 교구 구매(일회성) | E9: 창산용 문구류 | F9: 5751 | G9: 원 | H9: × | I9: 20 | J9: 개 | K9: x | L9: 28 | M9: 회 | N9: =F9*I9*L9 -> 3220560
C10: ■ 인쇄·복사·인화· 슬라이드 제작비 | G10: 원 | H10: × | J10: 부 | K10: x | M10: 회 | N10: =F10*I10*L10 -> 0
N11: =F11*I11*L11 -> 0
C12: ■ 외부 전문가 기술 활용비 | D12: 강사료 | E12: 주강사료 | F12: 100000 | G12: 원 | H12: × | I12: 8 | J12: 인 | K12: x | L12: 36 | M12: 회 | N12: =F12*I12*L12 -> 28800000
D13: 강사료 | E13: 보조강사료 | F13: 60000 | G13: 원 | H13: x | I13: 8 | J13: 인 | K13: x | L13: 36 | M13: 회 | N13: =F13*I13*L13 -> 17280000
D14: 외부전문가 활용 | E14: 자문 및 강사교육용 강사료 | F14: 100000 | G14: 원 | H14: x | I14: 1 | J14: 인 | K14: x | L14: 40 | M14: 회 | N14: =F14*I14*L14 -> 4000000
D15: 외부전문가 활용 | E15: 교육 프로그램 고도화 | F15: 250000 | G15: 원 | H15: × | I15: 1 | J15: 인 | K15: x | L15: 8 | M15: 회 | N15: =F15*I15*L15 -> 2000000
D16: 교통비 | E16: 교통비 | F16: 10000 | G16: 원 | H16: × | I16: 1 | J16: 인 | K16: x | L16: 28 | M16: 회 | N16: =F16*I16*L16 -> 280000
C17: ■ 일용직활용비 | D17: 단기근로자 활용 | E17: 안전관리요원 | F17: 20000 | G17: 원 | H17: x | I17: 8 | J17: 인 | K17: x | L17: 22 | M17: 회 | N17: =F17*I17*L17 -> 3520000
E18: 진행요원 | F18: 20000 | G18: 원 | H18: x | I18: 8 | J18: 인 | K18: x | L18: 22 | M18: 회 | N18: =F18*I18*L18 -> 3520000
C19: ■ 회의비 | D19: 행사 식다과비 | E19: 성과공유회, 강사교육 식비/임차료 | F19: 25000 | G19: 원 | H19: x | I19: 40 | J19: 인 | K19: x | L19: 1 | M19: 회 | N19: =F19*I19*L19 -> 1000000
D20: 교육생 식다과비 | E20: 강사. 학생 식비, 다과비 | F20: 10000 | G20: 원 | H20: x | I20: 22 | J20: 인 | K20: x | L20: 58 | M20: 회 | N20: =F20*I20*L20 -> 12760000
C21: ■ 제세공과·수수료·공공요금 | D21: 보험료 | E21: 보험료 | F21: 500 | G21: 원 | H21: x | I21: 20 | J21: 인 | K21: x | L21: 27 | M21: 회 | N21: =F21*I21*L21 -> 270000
N22: =F22*I22*L22 -> 0
C23: ■ 우편요금·택배비 | D23: 운송 비용 | E23: 택배비(교구, 노트북 등) | F23: 10000 | G23: 원 | H23: x | I23: 32 | J23: 반 | K23: x | L23: 3 | M23: 회 | N23: =F23*I23*L23 -> 960000
N24: =F24*I24*L24 -> 0
C25: ■ 기타 경비 | N25: =F25*I25*L25 -> 0
A26: 총계 | N26: =SUM(N5:N25) -> 94195560
A28: □ 작성가이드(※ 작성 전 안내 사항 반드시 확인 후 제출합니다) | U28: `
A29: [프로그램 운영비 편성 시 고려사항] 1. 실 작성 시 모든 폰트는 검은색으로 변경하여 작성 2. 제안 프로그램 수에 맞게 각각의 운영비 산출 필요(예. 제안프로그램 6종→세부 산출내역서 6부(시트) 필요) 3. 매입부가세가 발생하는 항목은 공급가액 기준으로 작성, 강사료, 보험료 등 매입부가세와 관련없는 항목은 실 집행금액 작성 4. 장비 및 교구재, 교육장 등 기준인원이 있는 항목은 각 항목별 비고란에 1대(개,실,부 등)당 기준인원수 필수 기입 5. 장비 및 교구재, 교육장 등의 금액(공급가액)은 실제 1대(개,실,부 등)당 임차 또는 구매 금액으로, 수량은 실 갯수 기입 (산출내역 수량 및 횟수 단위에 사람 수(人) 기준 단위로 변경 불가) 6. 단위는 가급적 변경을 지양하고, 불가피하게 변경하더라도 1식 등의 모호한 표현 금지 7. 프로그램별 산출이 어려운 행사, 강사 연수 비용 등은 총 필요 예산을 제안 프로그램별 적절하게 분배하여 기입 가능 8. 프로그램별 실제 운영에 필요한 비용으로 계상하되 전체 제안프로그램 운영비 및 사업관리비, 간접비의 합계가 신청유형별(새싹A/B) 최대 예산을 넘지않도록 주의

Sheet F프로그램
A1: (강화학습 자율주행AI 개발자(Sim2Real)) 프로그램 세부 산출내역서
A3: 비목 | B3: 세목 | C3: 세세목 | D3: 관리목 | E3: 산출내역 | N3: 금액 | O3: 비고
E4: 품명 | F4: 금액(공급가액) | G4: 단위 | H4: x | I4: 수량 | J4: 단위 | K4: x | L4: 횟수 | M4: 단위
B5: 사업운영비 | C5: ■ 시설·장비 임차비 | D5: 장비임차 | E5: 노트북 | F5: 40000 | G5: 원 | H5: × | I5: 9 | J5: 대 | K5: × | L5: 8 | M5: 개월 | N5: =F5*I5*L5 -> 2880000
D6: 장비임차 | E6: Gemini, ChatGPT 6.7 | F6: 210000 | G6: 원 | H6: × | I6: 1 | J6: 개 | K6: x | L6: 2 | M6: 개월 | N6: =F6*I6*L6 -> 420000
D7: 장비임차 | E7: 클로드6.7 | F7: 1155000 | G7: 원 | H7: × | I7: 1 | J7: 개 | K7: x | L7: 2 | M7: 개월 | N7: =F7*I7*L7 -> 2310000
C8: ■ 재료구입비 | D8: 교구 구매(교구, 범용성) | E8: 더듬이 자동차 + 배터리 | F8: 298000 | G8: 원 | H8: × | I8: 134 | J8: 개 | K8: x | L8: 1 | M8: 회 | N8: =F8*I8*L8 -> 39932000
D9: 교구 구매(일회성) | E9: 창산용 문구류 | F9: 5751 | G9: 원 | H9: × | I9: 20 | J9: 개 | K9: x | L9: 30 | M9: 회 | N9: =F9*I9*L9 -> 3450600
C10: ■ 인쇄·복사·인화· 슬라이드 제작비 | G10: 원 | H10: × | J10: 부 | K10: x | M10: 회 | N10: =F10*I10*L10 -> 0
N11: =F11*I11*L11 -> 0
C12: ■ 외부 전문가 기술 활용비 | D12: 강사료 | E12: 주강사료 | F12: 100000 | G12: 원 | H12: × | I12: 8 | J12: 인 | K12: x | L12: 37 | M12: 회 | N12: =F12*I12*L12 -> 29600000
D13: 강사료 | E13: 보조강사료 | F13: 60000 | G13: 원 | H13: x | I13: 8 | J13: 인 | K13: x | L13: 37 | M13: 회 | N13: =F13*I13*L13 -> 17760000
D14: 외부전문가 활용 | E14: 자문 및 강사교육용 강사료 | F14: 100000 | G14: 원 | H14: x | I14: 1 | J14: 인 | K14: x | L14: 45 | M14: 회 | N14: =F14*I14*L14 -> 4500000
D15: 외부전문가 활용 | E15: 교육 프로그램 고도화 | F15: 250000 | G15: 원 | H15: × | I15: 1 | J15: 인 | K15: x | L15: 12 | M15: 회 | N15: =F15*I15*L15 -> 3000000
D16: 교통비 | E16: 교통비 | F16: 10000 | G16: 원 | H16: × | I16: 1 | J16: 인 | K16: x | L16: 30 | M16: 회 | N16: =F16*I16*L16 -> 300000
C17: ■ 일용직활용비 | D17: 단기근로자 활용 | E17: 안전관리요원 | F17: 20000 | G17: 원 | H17: x | I17: 8 | J17: 인 | K17: x | L17: 25 | M17: 회 | N17: =F17*I17*L17 -> 4000000
E18: 진행요원 | F18: 20000 | G18: 원 | H18: x | I18: 8 | J18: 인 | K18: x | L18: 25 | M18: 회 | N18: =F18*I18*L18 -> 4000000
C19: ■ 회의비 | D19: 행사 식다과비 | E19: 성과공유회, 강사교육 식비/임차료 | F19: 25000 | G19: 원 | H19: x | I19: 40 | J19: 인 | K19: x | L19: 1 | M19: 회 | N19: =F19*I19*L19 -> 1000000
D20: 교육생 식다과비 | E20: 강사. 학생 식비, 다과비 | F20: 10000 | G20: 원 | H20: x | I20: 22 | J20: 인 | K20: x | L20: 60 | M20: 회 | N20: =F20*I20*L20 -> 13200000
C21: ■ 제세공과·수수료·공공요금 | D21: 보험료 | E21: 보험료 | F21: 500 | G21: 원 | H21: x | I21: 20 | J21: 인 | K21: x | L21: 29 | M21: 회 | N21: =F21*I21*L21 -> 290000
N22: =F22*I22*L22 -> 0
C23: ■ 우편요금·택배비 | D23: 운송 비용 | E23: 택배비(교구, 노트북 등) | F23: 10000 | G23: 원 | H23: x | I23: 32 | J23: 반 | K23: x | L23: 3 | M23: 회 | N23: =F23*I23*L23 -> 960000
N24: =F24*I24*L24 -> 0
C25: ■ 기타 경비 | N25: =F25*I25*L25 -> 0
A26: 총계 | N26: =SUM(N5:N25) -> 127602600
A28: □ 작성가이드(※ 작성 전 안내 사항 반드시 확인 후 제출합니다) | U28: `
A29: [프로그램 운영비 편성 시 고려사항] 1. 실 작성 시 모든 폰트는 검은색으로 변경하여 작성 2. 제안 프로그램 수에 맞게 각각의 운영비 산출 필요(예. 제안프로그램 6종→세부 산출내역서 6부(시트) 필요) 3. 매입부가세가 발생하는 항목은 공급가액 기준으로 작성, 강사료, 보험료 등 매입부가세와 관련없는 항목은 실 집행금액 작성 4. 장비 및 교구재, 교육장 등 기준인원이 있는 항목은 각 항목별 비고란에 1대(개,실,부 등)당 기준인원수 필수 기입 5. 장비 및 교구재, 교육장 등의 금액(공급가액)은 실제 1대(개,실,부 등)당 임차 또는 구매 금액으로, 수량은 실 갯수 기입 (산출내역 수량 및 횟수 단위에 사람 수(人) 기준 단위로 변경 불가) 6. 단위는 가급적 변경을 지양하고, 불가피하게 변경하더라도 1식 등의 모호한 표현 금지 7. 프로그램별 산출이 어려운 행사, 강사 연수 비용 등은 총 필요 예산을 제안 프로그램별 적절하게 분배하여 기입 가능 8. 프로그램별 실제 운영에 필요한 비용으로 계상하되 전체 제안프로그램 운영비 및 사업관리비, 간접비의 합계가 신청유형별(새싹A/B) 최대 예산을 넘지않도록 주의

Sheet G프로그램
A1: (피지컬AI 어플리케이션 개발자) 프로그램 세부 산출내역서
A3: 비목 | B3: 세목 | C3: 세세목 | D3: 관리목 | E3: 산출내역 | N3: 금액 | O3: 비고
E4: 품명 | F4: 금액(공급가액) | G4: 단위 | H4: x | I4: 수량 | J4: 단위 | K4: x | L4: 횟수 | M4: 단위
B5: 사업운영비 | C5: ■ 시설·장비 임차비 | D5: 장비임차 | E5: 노트북 | F5: 40000 | G5: 원 | H5: × | I5: 8 | J5: 대 | K5: × | L5: 8 | M5: 개월 | N5: =F5*I5*L5 -> 2560000
D6: 장비임차 | E6: ZOOM 1.7 | F6: 30000 | G6: 원 | H6: × | I6: 1 | J6: 대 | K6: x | L6: 17 | M6: 회 | N6: =F6*I6*L6 -> 510000
D7: 장비임차 | E7: Gemini, ChatGPT 6.7 | F7: 210000 | G7: 원 | H7: × | I7: 1 | J7: 개 | K7: x | L7: 2 | M7: 개월 | N7: =F7*I7*L7 -> 420000
D8: 장비임차 | E8: 클로드6.7 | F8: 1155000 | G8: 원 | H8: × | I8: 1 | J8: 개 | K8: x | L8: 2 | M8: 개월 | N8: =F8*I8*L8 -> 2310000
C9: ■ 재료구입비 | D9: 교구 구매(교구, 범용성) | E9: ESP32세트 + 클로드 | F9: 298000 | G9: 원 | H9: × | I9: 108 | J9: 개 | K9: x | L9: 1 | M9: 회 | N9: =F9*I9*L9 -> 32184000
D10: 교구 구매(일회성) | E10: 창산용 문구류 | F10: 5751 | G10: 원 | H10: × | I10: 20 | J10: 개 | K10: x | L10: 30 | M10: 회 | N10: =F10*I10*L10 -> 3450600
C11: ■ 인쇄·복사·인화· 슬라이드 제작비 | G11: 원 | H11: × | J11: 부 | K11: x | M11: 회 | N11: =F11*I11*L11 -> 0
N12: =F12*I12*L12 -> 0
C13: ■ 외부 전문가 기술 활용비 | D13: 강사료 | E13: 주강사료 | F13: 100000 | G13: 원 | H13: × | I13: 8 | J13: 인 | K13: x | L13: 36 | M13: 회 | N13: =F13*I13*L13 -> 28800000
D14: 강사료 | E14: 보조강사료 | F14: 60000 | G14: 원 | H14: x | I14: 8 | J14: 인 | K14: x | L14: 36 | M14: 회 | N14: =F14*I14*L14 -> 17280000
D15: 외부전문가 활용 | E15: 자문 및 강사교육용 강사료 | F15: 100000 | G15: 원 | H15: x | I15: 1 | J15: 인 | K15: x | L15: 46 | M15: 회 | N15: =F15*I15*L15 -> 4600000
D16: 외부전문가 활용 | E16: 교육 프로그램 고도화 | F16: 250000 | G16: 원 | H16: × | I16: 1 | J16: 인 | K16: x | L16: 12 | M16: 회 | N16: =F16*I16*L16 -> 3000000
D17: 교통비 | E17: 교통비 | F17: 10000 | G17: 원 | H17: × | I17: 1 | J17: 인 | K17: x | L17: 30 | M17: 회 | N17: =F17*I17*L17 -> 300000
C18: ■ 일용직활용비 | D18: 단기근로자 활용 | E18: 안전관리요원 | F18: 20000 | G18: 원 | H18: x | I18: 8 | J18: 인 | K18: x | L18: 25 | M18: 회 | N18: =F18*I18*L18 -> 4000000
E19: 진행요원 | F19: 20000 | G19: 원 | H19: x | I19: 8 | J19: 인 | K19: x | L19: 25 | M19: 회 | N19: =F19*I19*L19 -> 4000000
C20: ■ 회의비 | D20: 행사 식다과비 | E20: 성과공유회, 강사교육 식비/임차료 | F20: 25000 | G20: 원 | H20: x | I20: 40 | J20: 인 | K20: x | L20: 1 | M20: 회 | N20: =F20*I20*L20 -> 1000000
D21: 교육생 식다과비 | E21: 강사. 학생 식비, 다과비 | F21: 10000 | G21: 원 | H21: x | I21: 22 | J21: 인 | K21: x | L21: 60 | M21: 회 | N21: =F21*I21*L21 -> 13200000
C22: ■ 제세공과·수수료·공공요금 | D22: 보험료 | E22: 보험료 | F22: 500 | G22: 원 | H22: x | I22: 20 | J22: 인 | K22: x | L22: 29 | M22: 회 | N22: =F22*I22*L22 -> 290000
N23: =F23*I23*L23 -> 0
C24: ■ 우편요금·택배비 | D24: 운송 비용 | E24: 택배비(교구, 노트북 등) | F24: 10000 | G24: 원 | H24: x | I24: 32 | J24: 반 | K24: x | L24: 3 | M24: 회 | N24: =F24*I24*L24 -> 960000
N25: =F25*I25*L25 -> 0
C26: ■ 기타 경비 | N26: =F26*I26*L26 -> 0
A27: 총계 | N27: =SUM(N5:N26) -> 118864600
A29: □ 작성가이드(※ 작성 전 안내 사항 반드시 확인 후 제출합니다) | U29: `
A30: [프로그램 운영비 편성 시 고려사항] 1. 실 작성 시 모든 폰트는 검은색으로 변경하여 작성 2. 제안 프로그램 수에 맞게 각각의 운영비 산출 필요(예. 제안프로그램 6종→세부 산출내역서 6부(시트) 필요) 3. 매입부가세가 발생하는 항목은 공급가액 기준으로 작성, 강사료, 보험료 등 매입부가세와 관련없는 항목은 실 집행금액 작성 4. 장비 및 교구재, 교육장 등 기준인원이 있는 항목은 각 항목별 비고란에 1대(개,실,부 등)당 기준인원수 필수 기입 5. 장비 및 교구재, 교육장 등의 금액(공급가액)은 실제 1대(개,실,부 등)당 임차 또는 구매 금액으로, 수량은 실 갯수 기입 (산출내역 수량 및 횟수 단위에 사람 수(人) 기준 단위로 변경 불가) 6. 단위는 가급적 변경을 지양하고, 불가피하게 변경하더라도 1식 등의 모호한 표현 금지 7. 프로그램별 산출이 어려운 행사, 강사 연수 비용 등은 총 필요 예산을 제안 프로그램별 적절하게 분배하여 기입 가능 8. 프로그램별 실제 운영에 필요한 비용으로 계상하되 전체 제안프로그램 운영비 및 사업관리비, 간접비의 합계가 신청유형별(새싹A/B) 최대 예산을 넘지않도록 주의

Sheet 총 사업비 산출
A1: 총 사업비 산출내역서
A3: 비목 | B3: 세목 | C3: 세세목 | D3: 관리목 | E3: 산출내역 | N3: 금액 | O3: 구성비
E4: 품명 | F4: 금액(공급가액) | G4: 단위 | H4: x | I4: 수량 | J4: 단위 | K4: x | L4: 횟수 | M4: 단위
A5: 직접비 | B5: 사업운영비 | C5: ■ 시설·장비 임차비 | D5: 장비임차 | E5: 노트북 | F5: 40000 | G5: 원 | H5: × | I5: 62 | J5: 대 | K5: × | L5: 8 | M5: 개월 | N5: =F5*I5*L5 -> 19840000 | O5: =N33/N48 -> 0.850063 | P5: 노트북 1일 대여 62대 * 8개월
D6: 장비임차 | E6: ZOOM 1.7 | F6: 30000 | G6: 원 | H6: × | I6: 1 | J6: 대 | K6: x | L6: 34 | M6: 회 | N6: =F6*I6*L6 -> 1020000 | P6: 1. 서울,인천 및 전국 단위의 강사 교육 / 비대면 교육/ 보조 강사 수업 전 컨설팅, 안전 요원 교육 시에 활용 2. 여름철 태풍이나 비상시 비대면 교육 전환시 활용__1개/8개월, 7개/4개월 사용
D7: 장비임차 | E7: Gemini, ChatGPT 6.7 | F7: 210000 | G7: 원 | H7: × | I7: 1 | J7: 개 | K7: x | L7: 4 | M7: 회 | N7: =F7*I7*L7 -> 840000 | P7: 1. 서울,인천 및 전국단위의 강사교육/비대면교육/보조강사 수업전 컨설팅, 안전요원 교육 시에 활용 2. 여름철 태풍이나 비상시 비대면 교육 전환 시 활용__ 월간 구독료 *4개월
D8: 장비임차 | E8: 클로드6.7 | F8: 1155000 | G8: 원 | H8: × | I8: 1 | J8: 개 | K8: x | L8: 4 | M8: 회 | N8: =F8*I8*L8 -> 4620000 | P8: 고등학생 프로그램(피지컬 AI 어필리케이션 제작자)의 강사 교육 및 교육 준비 상황에서 강사와 강사 교육 전문가에게 활용_월간 구독료 *4개월
D9: 장비임차 | E9: 캔바5 | F9: 230000 | G9: 원 | H9: × | I9: 1 | J9: 개 | K9: x | L9: 1 | M9: 회 | N9: =F9*I9*L9 -> 230000 | P9: 학생들의 수업 시간에 배운 내용의 결과물 시각화 제작) 청소년 센터,도서관 교육 시 활용_ 월간 구독료 *1개월
C10: ■ 재료구입비 | D10: 교구 구매 (교구, 범용성) | E10: 무선 카메라 | F10: 55000 | G10: 원 | H10: × | I10: 186 | J10: 개 | K10: x | L10: 1 | M10: 회 | N10: =F10*I10*L10 -> 10230000
D11: 교구 구매 (교구, 범용성) | E11: 오토바이, 주행코스, 배터리 | F11: 298000 | G11: 원 | H11: × | I11: 201 | J11: 개 | K11: x | L11: 1 | M11: 회 | N11: =F11*I11*L11 -> 59898000
D12: 교구 구매 (교구, 범용성) | E12: 리치보드, 디스플레이류(4종) | F12: 77000 | G12: 원 | H12: × | I12: 169 | J12: 개 | K12: x | L12: 1 | M12: 회 | N12: =F12*I12*L12 -> 13013000
D13: 교구 구매 (교구, 범용성) | E13: 캐터필러, 무선캠, 집게, 배터리 | F13: 298000 | G13: 원 | H13: × | I13: 218 | J13: 개 | K13: x | L13: 1 | M13: 회 | N13: =F13*I13*L13 -> 64964000
D14: 교구 구매 (교구, 범용성) | E14: 리치보드, 센서류(5종) | F14: 77000 | G14: 원 | H14: × | I14: 175 | J14: 개 | K14: x | L14: 1 | M14: 회 | N14: =F14*I14*L14 -> 13475000
D15: 교구 구매 (교구, 범용성) | E15: 더듬이 자동차 + 배터리 | F15: 298000 | G15: 원 | H15: × | I15: 134 | J15: 개 | K15: x | L15: 1 | M15: 회 | N15: =F15*I15*L15 -> 39932000
D16: 교구 구매 (교구, 범용성) | E16: ESP32세트 + 클로드 | F16: 298000 | G16: 원 | H16: × | I16: 108 | J16: 개 | K16: x | L16: 1 | M16: 회 | N16: =F16*I16*L16 -> 32184000
D17: 교구 구매(일회성) | E17: 창산용 문구류 | F17: 5751 | G17: 원 | H17: × | I17: 20 | J17: 개 | K17: x | L17: 200 | M17: 회 | N17: =F17*I17*L17 -> 23004000
C18: ■ 인쇄·복사·인화· 슬라이드 제작비 | G18: 원 | H18: × | J18: 부 | K18: x | M18: 회 | N18: =F18*I18*L18 -> 0
C19: ■ 외부 전문가 기술 활용비 | D19: 강사료 | E19: 주강사료 | F19: 100000 | G19: 원 | H19: × | I19: 8 | J19: 인 | K19: x | L19: 253 | M19: 회 | N19: =F19*I19*L19 -> 202400000
D20: 강사료 | E20: 보조강사료 | F20: 60000 | G20: 원 | H20: x | I20: 8 | J20: 인 | K20: x | L20: 253 | M20: 회 | N20: =F20*I20*L20 -> 121440000
D21: 외부전문가 활용 | E21: 자문 및 강사교육용 강사료 | F21: 100000 | G21: 원 | H21: x | I21: 1 | J21: 인 | K21: x | L21: 291 | M21: 회 | N21: =F21*I21*L21 -> 29100000
D22: 외부전문가 활용 | E22: 교육 프로그램 고도화 | F22: 250000 | G22: 원 | H22: × | I22: 1 | J22: 인 | K22: x | L22: 64 | M22: 회 | N22: =F22*I22*L22 -> 16000000
D23: 교통비 | E23: 교통비 | F23: 10000 | G23: 원 | H23: × | I23: 1 | J23: 인 | K23: x | L23: 200 | M23: 회 | N23: =F23*I23*L23 -> 2000000
C24: ■ 일용직활용비 | D24: 단기근로자 활용 | E24: 안전관리요원 | F24: 20000 | G24: 원 | H24: x | I24: 8 | J24: 인 | K24: x | L24: 160 | M24: 회 | N24: =F24*I24*L24 -> 25600000
E25: 진행요원 | F25: 20000 | G25: 원 | H25: x | I25: 8 | J25: 인 | K25: x | L25: 160 | M25: 회 | N25: =F25*I25*L25 -> 25600000
C26: ■ 회의비 | D26: 행사 식다과비 | E26: 성과공유회, 강사교육 식비/임차료 | F26: 25000 | G26: 원 | H26: x | I26: 40 | J26: 인 | K26: x | L26: 6 | M26: 회 | N26: =F26*I26*L26 -> 6000000
D27: 교육생 식다과비 | E27: 강사. 학생 식비, 다과비 | F27: 10000 | G27: 원 | H27: x | I27: 22 | J27: 인 | K27: x | L27: 410 | M27: 회 | N27: =F27*I27*L27 -> 90200000
C28: ■ 제세공과·수수료·공공요금 | D28: 보험료 | E28: 보험료 | F28: 500 | G28: 원 | H28: x | I28: 20 | J28: 인 | K28: x | L28: 193 | M28: 회 | N28: =F28*I28*L28 -> 1930000
N29: =F29*I29*L29 -> 0
C30: ■ 우편요금·택배비 | D30: 운송 비용 | E30: 택배비(교구, 노트북 등) | F30: 10000 | G30: 원 | H30: x | I30: 32 | J30: 반 | K30: x | L30: 19 | M30: 회 | N30: =F30*I30*L30 -> 6080000
N31: =F31*I31*L31 -> 0
C32: ■ 기타 경비 | N32: =F32*I32*L32 -> 0
B33: 사업운영비 소계(1) | N33: =SUM(N5:N32) -> 809600000
B34: 사업관리비 | C34: ■ 내부 인건비 | D34: 참여 인력 인건비 | E34: 행정연구원(강혜영) | F34: 4800000 | G34: 원 | H34: × | I34: 1 | J34: (참여율) | K34: x | L34: 7 | M34: 개월 | N34: =F34*I34*L34 -> 33600000 | O34: =N47/N48 -> 0.149937
E35: 행정연구원(이상원) | F35: 3600000 | G35: 원 | H35: × | I35: 1 | J35: (참여율) | K35: x | L35: 8 | M35: 개월 | N35: =F35*I35*L35 -> 28800000 | P35: 회의비 5월분(200만원)
E36: 학생연구원(정의손) | F36: 2200000 | G36: 원 | H36: × | I36: 1 | J36: (참여율) | K36: x | L36: 8 | M36: 개월 | N36: =F36*I36*L36 -> 17600000
E37: 학생연구원(김현일) | F37: 2200000 | G37: 원 | H37: × | I37: 1 | J37: (참여율) | K37: x | L37: 8 | M37: 개월 | N37: =F37*I37*L37 -> 17600000
E38: 보조연구원(학부) | F38: 1200000 | G38: 원 | H38: × | I38: 0.25 | J38: (참여율) | K38: x | L38: 8 | M38: 개월 | N38: =F38*I38*L38 -> 2400000
E39: 보조연구원(학부) | F39: 1200000 | G39: 원 | H39: × | I39: 0.5 | J39: (참여율) | K39: x | L39: 8 | M39: 개월 | N39: =F39*I39*L39 -> 4800000
D40: 참여 인력 사업 수당 | E40: 미지급인력 | F40: 800000 | G40: 원 | H40: × | I40: 1 | J40: 인 | K40: x | L40: 8 | M40: 개월 | N40: =F40*I40*L40 -> 6400000
E41: 미지급인력 | F41: 100000 | G41: 원 | H41: × | I41: 1 | J41: 인 | K41: x | L41: 8 | M41: 개월 | N41: =F41*I41*L41 -> 800000
...

Sheet 8억기준
A1: 총 사업비 산출내역서
A3: 비목 | B3: 세목 | C3: 세세목 | D3: 관리목 | E3: 산출내역 | N3: 금액 | O3: 구성비
E4: 품명 | F4: 금액(공급가액) | G4: 단위 | H4: x | I4: 수량 | J4: 단위 | K4: x | L4: 횟수 | M4: 단위
A5: 직접비 | B5: 사업운영비 | C5: ■ 시설·장비 임차비 | D5: 장비임차 | E5: 노트북 | F5: 40000 | G5: 원 | H5: × | I5: 62 | J5: 대 | K5: × | L5: 8 | M5: 개월 | N5: =F5*I5*L5 -> 19840000 | O5: =N33/N48 -> 0.87066597
D6: 장비임차 | E6: ZOOM 1.7 | F6: 30000 | G6: 원 | H6: × | I6: 1 | J6: 대 | K6: x | L6: 34 | M6: 회 | N6: =F6*I6*L6 -> 1020000
D7: 장비임차 | E7: Gemini, ChatGPT 6.7 | F7: 210000 | G7: 원 | H7: × | I7: 1 | J7: 개 | K7: x | L7: 4 | M7: 회 | N7: =F7*I7*L7 -> 840000
D8: 장비임차 | E8: 클로드6.7 | F8: 1155000 | G8: 원 | H8: × | I8: 1 | J8: 개 | K8: x | L8: 4 | M8: 회 | N8: =F8*I8*L8 -> 4620000
D9: 장비임차 | E9: 캔바5 | F9: 230000 | G9: 원 | H9: × | I9: 1 | J9: 개 | K9: x | L9: 1 | M9: 회 | N9: =F9*I9*L9 -> 230000
C10: ■ 재료구입비 | D10: 교구 구매 (교구, 범용성) | E10: 무선 카메라 | F10: 55000 | G10: 원 | H10: × | I10: 186 | J10: 개 | K10: x | L10: 1 | M10: 회 | N10: =F10*I10*L10 -> 10230000
D11: 교구 구매 (교구, 범용성) | E11: 오토바이, 주행코스, 배터리 | F11: 298000 | G11: 원 | H11: × | I11: 201 | J11: 개 | K11: x | L11: 1 | M11: 회 | N11: =F11*I11*L11 -> 59898000
D12: 교구 구매 (교구, 범용성) | E12: 리치보드, 디스플레이류(4종) | F12: 77000 | G12: 원 | H12: × | I12: 169 | J12: 개 | K12: x | L12: 1 | M12: 회 | N12: =F12*I12*L12 -> 13013000
D13: 교구 구매 (교구, 범용성) | E13: 캐터필러, 무선캠, 집게, 배터리 | F13: 298000 | G13: 원 | H13: × | I13: 218 | J13: 개 | K13: x | L13: 1 | M13: 회 | N13: =F13*I13*L13 -> 64964000
D14: 교구 구매 (교구, 범용성) | E14: 리치보드, 센서류(5종) | F14: 77000 | G14: 원 | H14: × | I14: 175 | J14: 개 | K14: x | L14: 1 | M14: 회 | N14: =F14*I14*L14 -> 13475000
D15: 교구 구매 (교구, 범용성) | E15: 더듬이 자동차 + 배터리 | F15: 298000 | G15: 원 | H15: × | I15: 134 | J15: 개 | K15: x | L15: 1 | M15: 회 | N15: =F15*I15*L15 -> 39932000
D16: 교구 구매 (교구, 범용성) | E16: ESP32세트 + 클로드 | F16: 298000 | G16: 원 | H16: × | I16: 108 | J16: 개 | K16: x | L16: 1 | M16: 회 | N16: =F16*I16*L16 -> 32184000
D17: 교구 구매(일회성) | E17: 창산용 문구류 | F17: 5751 | G17: 원 | H17: × | I17: 20 | J17: 개 | K17: x | L17: 200 | M17: 회 | N17: =F17*I17*L17 -> 23004000
C18: ■ 인쇄·복사·인화· 슬라이드 제작비 | G18: 원 | H18: × | J18: 부 | K18: x | M18: 회 | N18: =F18*I18*L18 -> 0
C19: ■ 외부 전문가 기술 활용비 | D19: 강사료 | E19: 주강사료 | F19: 75000 | G19: 원 | H19: × | I19: 8 | J19: 인 | K19: x | L19: 253 | M19: 회 | N19: =F19*I19*L19 -> 151800000
D20: 강사료 | E20: 보조강사료 | F20: 45000 | G20: 원 | H20: x | I20: 8 | J20: 인 | K20: x | L20: 253 | M20: 회 | N20: =F20*I20*L20 -> 91080000
D21: 외부전문가 활용 | E21: 자문 및 강사교육용 강사료 | F21: 100000 | G21: 원 | H21: x | I21: 1 | J21: 인 | K21: x | L21: 0 | M21: 회 | N21: =F21*I21*L21 -> 0 | P21: 2차 협약금 입금 후 처리예정
D22: 외부전문가 활용 | E22: 교육 프로그램 고도화 | F22: 250000 | G22: 원 | H22: × | I22: 1 | J22: 인 | K22: x | L22: 0 | M22: 회 | N22: =F22*I22*L22 -> 0 | P22: 2차 협약금 입금 후 처리예정
D23: 교통비 | E23: 교통비 | F23: 10000 | G23: 원 | H23: × | I23: 1 | J23: 인 | K23: x | L23: 179 | M23: 회 | N23: =F23*I23*L23 -> 1790000
C24: ■ 일용직활용비 | D24: 단기근로자 활용 | E24: 안전관리요원 | F24: 20000 | G24: 원 | H24: x | I24: 8 | J24: 인 | K24: x | L24: 160 | M24: 회 | N24: =F24*I24*L24 -> 25600000
E25: 진행요원 | F25: 20000 | G25: 원 | H25: x | I25: 8 | J25: 인 | K25: x | L25: 160 | M25: 회 | N25: =F25*I25*L25 -> 25600000
C26: ■ 회의비 | D26: 행사 식다과비 | E26: 성과공유회, 강사교육 식비/임차료 | F26: 25000 | G26: 원 | H26: x | I26: 40 | J26: 인 | K26: x | L26: 6 | M26: 회 | N26: =F26*I26*L26 -> 6000000
D27: 교육생 식다과비 | E27: 강사. 학생 식비, 다과비 | F27: 10000 | G27: 원 | H27: x | I27: 22 | J27: 인 | K27: x | L27: 331 | M27: 회 | N27: =F27*I27*L27 -> 72820000
C28: ■ 제세공과·수수료·공공요금 | D28: 보험료 | E28: 보험료 | F28: 500 | G28: 원 | H28: x | I28: 20 | J28: 인 | K28: x | L28: 143 | M28: 회 | N28: =F28*I28*L28 -> 1430000
N29: =F29*I29*L29 -> 0
C30: ■ 우편요금·택배비 | D30: 운송 비용 | E30: 택배비(교구, 노트북 등) | F30: 10000 | G30: 원 | H30: x | I30: 32 | J30: 반 | K30: x | L30: 19 | M30: 회 | N30: =F30*I30*L30 -> 6080000
N31: =F31*I31*L31 -> 0
C32: ■ 기타 경비 | N32: =F32*I32*L32 -> 0
B33: 사업운영비 소계(1) | N33: =SUM(N5:N32) -> 665450000
B34: 사업관리비 | C34: ■ 내부 인건비 | D34: 참여 인력 인건비 | E34: 행정연구원(강혜영) | F34: 4800000 | G34: 원 | H34: × | I34: 1 | J34: (참여율) | K34: x | L34: 5 | M34: 개월 | N34: =F34*I34*L34 -> 24000000 | O34: =N47/N48 -> 0.12933403
E35: 행정연구원(이상원) | F35: 3600000 | G35: 원 | H35: × | I35: 1 | J35: (참여율) | K35: x | L35: 6 | M35: 개월 | N35: =F35*I35*L35 -> 21600000
E36: 학생연구원(정의손) | F36: 2200000 | G36: 원 | H36: × | I36: 1 | J36: (참여율) | K36: x | L36: 6 | M36: 개월 | N36: =F36*I36*L36 -> 13200000
E37: 학생연구원(김현일) | F37: 2200000 | G37: 원 | H37: × | I37: 1 | J37: (참여율) | K37: x | L37: 6 | M37: 개월 | N37: =F37*I37*L37 -> 13200000
E38: 보조연구원(학부) | F38: 1200000 | G38: 원 | H38: × | I38: 0.25 | J38: (참여율) | K38: x | L38: 6 | M38: 개월 | N38: =F38*I38*L38 -> 1800000
E39: 보조연구원(학부) | F39: 1200000 | G39: 원 | H39: × | I39: 0.5 | J39: (참여율) | K39: x | L39: 6 | M39: 개월 | N39: =F39*I39*L39 -> 3600000
D40: 참여 인력 사업 수당 | E40: 미지급인력 | F40: 800000 | G40: 원 | H40: × | I40: 1 | J40: 인 | K40: x | L40: 0 | M40: 개월 | N40: =F40*I40*L40 -> 0 | P40: 2차 협약금 입금 후 처리예정
E41: 미지급인력 | F41: 100000 | G41: 원 | H41: × | I41: 1 | J41: 인 | K41: x | L41: 0 | M41: 개월 | N41: =F41*I41*L41 -> 0 | P41: 2차 협약금 입금 후 처리예정
...

Sheet 8억기준_산단제출용
A1: 총 사업비 산출내역서
A3: 비목 | B3: 세목 | C3: 세세목 | D3: 관리목 | E3: 산출내역 | N3: 금액 | O3: 구성비
E4: 품명 | F4: 금액(공급가액) | G4: 단위 | H4: x | I4: 수량 | J4: 단위 | K4: x | L4: 횟수 | M4: 단위
A5: 직접비 | B5: 사업운영비 | C5: ■ 시설·장비 임차비 | D5: 장비임차 | E5: 노트북 | F5: 40000 | G5: 원 | H5: × | I5: 62 | J5: 대 | K5: × | L5: 8 | M5: 개월 | N5: =F5*I5*L5 -> 19840000 | O5: =N33/N48 -> 0.87066597
D6: 장비임차 | E6: ZOOM 1.7 | F6: 30000 | G6: 원 | H6: × | I6: 1 | J6: 대 | K6: x | L6: 34 | M6: 회 | N6: =F6*I6*L6 -> 1020000
D7: 장비임차 | E7: Gemini, ChatGPT 6.7 | F7: 210000 | G7: 원 | H7: × | I7: 1 | J7: 개 | K7: x | L7: 4 | M7: 회 | N7: =F7*I7*L7 -> 840000
D8: 장비임차 | E8: 클로드6.7 | F8: 1155000 | G8: 원 | H8: × | I8: 1 | J8: 개 | K8: x | L8: 4 | M8: 회 | N8: =F8*I8*L8 -> 4620000
D9: 장비임차 | E9: 캔바5 | F9: 230000 | G9: 원 | H9: × | I9: 1 | J9: 개 | K9: x | L9: 1 | M9: 회 | N9: =F9*I9*L9 -> 230000
C10: ■ 재료구입비 | D10: 교구 구매 (교구, 범용성) | E10: 무선 카메라 | F10: 55000 | G10: 원 | H10: × | I10: 186 | J10: 개 | K10: x | L10: 1 | M10: 회 | N10: =F10*I10*L10 -> 10230000
D11: 교구 구매 (교구, 범용성) | E11: 오토바이, 주행코스, 배터리 | F11: 298000 | G11: 원 | H11: × | I11: 201 | J11: 개 | K11: x | L11: 1 | M11: 회 | N11: =F11*I11*L11 -> 59898000
D12: 교구 구매 (교구, 범용성) | E12: 리치보드, 디스플레이류(4종) | F12: 77000 | G12: 원 | H12: × | I12: 169 | J12: 개 | K12: x | L12: 1 | M12: 회 | N12: =F12*I12*L12 -> 13013000
D13: 교구 구매 (교구, 범용성) | E13: 캐터필러, 무선캠, 집게, 배터리 | F13: 298000 | G13: 원 | H13: × | I13: 218 | J13: 개 | K13: x | L13: 1 | M13: 회 | N13: =F13*I13*L13 -> 64964000
D14: 교구 구매 (교구, 범용성) | E14: 리치보드, 센서류(5종) | F14: 77000 | G14: 원 | H14: × | I14: 175 | J14: 개 | K14: x | L14: 1 | M14: 회 | N14: =F14*I14*L14 -> 13475000
D15: 교구 구매 (교구, 범용성) | E15: 더듬이 자동차 + 배터리 | F15: 298000 | G15: 원 | H15: × | I15: 134 | J15: 개 | K15: x | L15: 1 | M15: 회 | N15: =F15*I15*L15 -> 39932000
D16: 교구 구매 (교구, 범용성) | E16: ESP32세트 + 클로드 | F16: 298000 | G16: 원 | H16: × | I16: 108 | J16: 개 | K16: x | L16: 1 | M16: 회 | N16: =F16*I16*L16 -> 32184000
D17: 교구 구매(일회성) | E17: 창산용 문구류 | F17: 5751 | G17: 원 | H17: × | I17: 20 | J17: 개 | K17: x | L17: 200 | M17: 회 | N17: =F17*I17*L17 -> 23004000
C18: ■ 인쇄·복사·인화· 슬라이드 제작비 | G18: 원 | H18: × | J18: 부 | K18: x | M18: 회 | N18: =F18*I18*L18 -> 0
C19: ■ 외부 전문가 기술 활용비 | D19: 강사료 | E19: 주강사료 | F19: 75000 | G19: 원 | H19: × | I19: 8 | J19: 인 | K19: x | L19: 253 | M19: 회 | N19: =F19*I19*L19 -> 151800000
D20: 강사료 | E20: 보조강사료 | F20: 45000 | G20: 원 | H20: x | I20: 8 | J20: 인 | K20: x | L20: 253 | M20: 회 | N20: =F20*I20*L20 -> 91080000
D21: 외부전문가 활용 | E21: 자문 및 강사교육용 강사료 | F21: 100000 | G21: 원 | H21: x | I21: 1 | J21: 인 | K21: x | L21: 0 | M21: 회 | N21: =F21*I21*L21 -> 0 | P21: 2차 협약금 입금 후 처리예정
D22: 외부전문가 활용 | E22: 교육 프로그램 고도화 | F22: 250000 | G22: 원 | H22: × | I22: 1 | J22: 인 | K22: x | L22: 0 | M22: 회 | N22: =F22*I22*L22 -> 0 | P22: 2차 협약금 입금 후 처리예정
D23: 교통비 | E23: 교통비 | F23: 10000 | G23: 원 | H23: × | I23: 1 | J23: 인 | K23: x | L23: 179 | M23: 회 | N23: =F23*I23*L23 -> 1790000
C24: ■ 일용직활용비 | D24: 단기근로자 활용 | E24: 안전관리요원 | F24: 20000 | G24: 원 | H24: x | I24: 8 | J24: 인 | K24: x | L24: 160 | M24: 회 | N24: =F24*I24*L24 -> 25600000
E25: 진행요원 | F25: 20000 | G25: 원 | H25: x | I25: 8 | J25: 인 | K25: x | L25: 160 | M25: 회 | N25: =F25*I25*L25 -> 25600000
C26: ■ 회의비 | D26: 행사 식다과비 | E26: 성과공유회, 강사교육 식비/임차료 | F26: 25000 | G26: 원 | H26: x | I26: 40 | J26: 인 | K26: x | L26: 6 | M26: 회 | N26: =F26*I26*L26 -> 6000000
D27: 교육생 식다과비 | E27: 강사. 학생 식비, 다과비 | F27: 10000 | G27: 원 | H27: x | I27: 22 | J27: 인 | K27: x | L27: 331 | M27: 회 | N27: =F27*I27*L27 -> 72820000
C28: ■ 제세공과·수수료·공공요금 | D28: 보험료 | E28: 보험료 | F28: 500 | G28: 원 | H28: x | I28: 20 | J28: 인 | K28: x | L28: 143 | M28: 회 | N28: =F28*I28*L28 -> 1430000
N29: =F29*I29*L29 -> 0
C30: ■ 우편요금·택배비 | D30: 운송 비용 | E30: 택배비(교구, 노트북 등) | F30: 10000 | G30: 원 | H30: x | I30: 32 | J30: 반 | K30: x | L30: 19 | M30: 회 | N30: =F30*I30*L30 -> 6080000
N31: =F31*I31*L31 -> 0
C32: ■ 기타 경비 | N32: =F32*I32*L32 -> 0
B33: 사업운영비 소계(1) | N33: =SUM(N5:N32) -> 665450000
